Workbook

Sheet Bridge Summary
B2: Bridge Portfolio
B4: Summary by Segment:
C5: Loan Count | D5: Asset Count | E5: Current | F5: DQ 1-29 | G5: DQ 30-59 | H5: DQ 60-89 | I5: DQ 90+ | J5: REO | K5: Total | L5: Total Ex. REO | N5: DQ 30+ % | O5: DQ 60+ % | P5: DQ 90+ % | Q5: REO %
B6: Legacy | C6: =COUNTIFS('Bridge Loan'!$AM:$AM,'Bridge Summary'!$B6) | D6: =COUNTIFS('Bridge Asset'!$BU:$BU,'Bridge Summary'!$B6) | E6: =SUMIFS('Bridge Asset'!$AJ:$AJ,'Bridge Asset'!$BU:$BU,'Bridge Summary'!$B6,'Bridge Asset'!$CR:$CR,'Bridge Summary'!E$5) | F6: =SUMIFS('Bridge Asset'!$AJ:$AJ,'Bridge Asset'!$BU:$BU,'Bridge Summary'!$B6,'Bridge Asset'!$CR:$CR,'Bridge Summary'!F$5) | G6: =SUMIFS('Bridge Asset'!$AJ:$AJ,'Bridge Asset'!$BU:$BU,'Bridge Summary'!$B6,'Bridge Asset'!$CR:$CR,'Bridge Summary'!G$5) | H6: =SUMIFS('Bridge Asset'!$AJ:$AJ,'Bridge Asset'!$BU:$BU,'Bridge Summary'!$B6,'Bridge Asset'!$CR:$CR,'Bridge Summary'!H$5) | I6: =SUMIFS('Bridge Asset'!$AJ:$AJ,'Bridge Asset'!$BU:$BU,'Bridge Summary'!$B6,'Bridge Asset'!$CR:$CR,'Bridge Summary'!I$5) | J6: =SUMIFS('Bridge Asset'!$AJ:$AJ,'Bridge Asset'!$BU:$BU,'Bridge Summary'!$B6,'Bridge Asset'!$CR:$CR,'Bridge Summary'!J$5) | K6: =SUM($E6:$J6) | L6: =+$K6-$J6 | N6: =IFERROR(SUM($G6:$I6)/$L6,"N/A") | O6: =IFERROR(SUM($H6:$I6)/$L6,"N/A") | P6: =IFERROR($I6/$L6,"N/A") | Q6: =IFERROR($J6/$K6,"N/A")
B7: Securitized Bridge | C7: =SUM(C$8:C$14) | D7: =SUM(D$8:D$14) | E7: =SUM(E$8:E$14) | F7: =SUM(F$8:F$14) | G7: =SUM(G$8:G$14) | H7: =SUM(H$8:H$14) | I7: =SUM(I$8:I$14) | J7: =SUM(J$8:J$14) | K7: =SUM($E7:$J7) | L7: =+$K7-$J7 | N7: =IFERROR(SUM($G7:$I7)/$L7,"N/A") | O7: =IFERROR(SUM($H7:$I7)/$L7,"N/A") | P7: =IFERROR($I7/$L7,"N/A") | Q7: =IFERROR($J7/$K7,"N/A")
B8: CAFL 2024-RTL1 CPP | C8: =COUNTIFS('Bridge Loan'!$AM:$AM,'Bridge Summary'!$B$7,'Bridge Loan'!$D:$D,'Bridge Summary'!$B8) | D8: =COUNTIFS('Bridge Asset'!$BU:$BU,'Bridge Summary'!$B$7,'Bridge Asset'!$D:$D,'Bridge Summary'!$B8) | E8: =SUMIFS('Bridge Asset'!$AJ:$AJ,'Bridge Asset'!$BU:$BU,'Bridge Summary'!$B$7,'Bridge Asset'!$D:$D,'Bridge Summary'!$B8,'Bridge Asset'!$CR:$CR,'Bridge Summary'!E$5) | F8: =SUMIFS('Bridge Asset'!$AJ:$AJ,'Bridge Asset'!$BU:$BU,'Bridge Summary'!$B$7,'Bridge Asset'!$D:$D,'Bridge Summary'!$B8,'Bridge Asset'!$CR:$CR,'Bridge Summary'!F$5) | G8: =SUMIFS('Bridge Asset'!$AJ:$AJ,'Bridge Asset'!$BU:$BU,'Bridge Summary'!$B$7,'Bridge Asset'!$D:$D,'Bridge Summary'!$B8,'Bridge Asset'!$CR:$CR,'Bridge Summary'!G$5) | H8: =SUMIFS('Bridge Asset'!$AJ:$AJ,'Bridge Asset'!$BU:$BU,'Bridge Summary'!$B$7,'Bridge Asset'!$D:$D,'Bridge Summary'!$B8,'Bridge Asset'!$CR:$CR,'Bridge Summary'!H$5) | I8: =SUMIFS('Bridge Asset'!$AJ:$AJ,'Bridge Asset'!$BU:$BU,'Bridge Summary'!$B$7,'Bridge Asset'!$D:$D,'Bridge Summary'!$B8,'Bridge Asset'!$CR:$CR,'Bridge Summary'!I$5) | J8: =SUMIFS('Bridge Asset'!$AJ:$AJ,'Bridge Asset'!$BU:$BU,'Bridge Summary'!$B$7,'Bridge Asset'!$D:$D,'Bridge Summary'!$B8,'Bridge Asset'!$CR:$CR,'Bridge Summary'!J$5) | K8: =SUM($E8:$J8) | L8: =+$K8-$J8 | N8: =IFERROR(SUM($G8:$I8)/$L8,"N/A") | O8: =IFERROR(SUM($H8:$I8)/$L8,"N/A") | P8: =IFERROR($I8/$L8,"N/A") | Q8: =IFERROR($J8/$K8,"N/A")
B9: CAFL 2024-RTL1 CV | C9: =COUNTIFS('Bridge Loan'!$AM:$AM,'Bridge Summary'!$B$7,'Bridge Loan'!$D:$D,'Bridge Summary'!$B9) | D9: =COUNTIFS('Bridge Asset'!$BU:$BU,'Bridge Summary'!$B$7,'Bridge Asset'!$D:$D,'Bridge Summary'!$B9) | E9: =SUMIFS('Bridge Asset'!$AJ:$AJ,'Bridge Asset'!$BU:$BU,'Bridge Summary'!$B$7,'Bridge Asset'!$D:$D,'Bridge Summary'!$B9,'Bridge Asset'!$CR:$CR,'Bridge Summary'!E$5) | F9: =SUMIFS('Bridge Asset'!$AJ:$AJ,'Bridge Asset'!$BU:$BU,'Bridge Summary'!$B$7,'Bridge Asset'!$D:$D,'Bridge Summary'!$B9,'Bridge Asset'!$CR:$CR,'Bridge Summary'!F$5) | G9: =SUMIFS('Bridge Asset'!$AJ:$AJ,'Bridge Asset'!$BU:$BU,'Bridge Summary'!$B$7,'Bridge Asset'!$D:$D,'Bridge Summary'!$B9,'Bridge Asset'!$CR:$CR,'Bridge Summary'!G$5) | H9: =SUMIFS('Bridge Asset'!$AJ:$AJ,'Bridge Asset'!$BU:$BU,'Bridge Summary'!$B$7,'Bridge Asset'!$D:$D,'Bridge Summary'!$B9,'Bridge Asset'!$CR:$CR,'Bridge Summary'!H$5) | I9: =SUMIFS('Bridge Asset'!$AJ:$AJ,'Bridge Asset'!$BU:$BU,'Bridge Summary'!$B$7,'Bridge Asset'!$D:$D,'Bridge Summary'!$B9,'Bridge Asset'!$CR:$CR,'Bridge Summary'!I$5) | J9: =SUMIFS('Bridge Asset'!$AJ:$AJ,'Bridge Asset'!$BU:$BU,'Bridge Summary'!$B$7,'Bridge Asset'!$D:$D,'Bridge Summary'!$B9,'Bridge Asset'!$CR:$CR,'Bridge Summary'!J$5) | K9: =SUM($E9:$J9) | L9: =+$K9-$J9 | N9: =IFERROR(SUM($G9:$I9)/$L9,"N/A") | O9: =IFERROR(SUM($H9:$I9)/$L9,"N/A") | P9: =IFERROR($I9/$L9,"N/A") | Q9: =IFERROR($J9/$K9,"N/A")
B10: CAFL 2025-RRTL1 CPP | C10: =COUNTIFS('Bridge Loan'!$AM:$AM,'Bridge Summary'!$B$7,'Bridge Loan'!$D:$D,'Bridge Summary'!$B10) | D10: =COUNTIFS('Bridge Asset'!$BU:$BU,'Bridge Summary'!$B$7,'Bridge Asset'!$D:$D,'Bridge Summary'!$B10) | E10: =SUMIFS('Bridge Asset'!$AJ:$AJ,'Bridge Asset'!$BU:$BU,'Bridge Summary'!$B$7,'Bridge Asset'!$D:$D,'Bridge Summary'!$B10,'Bridge Asset'!$CR:$CR,'Bridge Summary'!E$5) | F10: =SUMIFS('Bridge Asset'!$AJ:$AJ,'Bridge Asset'!$BU:$BU,'Bridge Summary'!$B$7,'Bridge Asset'!$D:$D,'Bridge Summary'!$B10,'Bridge Asset'!$CR:$CR,'Bridge Summary'!F$5) | G10: =SUMIFS('Bridge Asset'!$AJ:$AJ,'Bridge Asset'!$BU:$BU,'Bridge Summary'!$B$7,'Bridge Asset'!$D:$D,'Bridge Summary'!$B10,'Bridge Asset'!$CR:$CR,'Bridge Summary'!G$5) | H10: =SUMIFS('Bridge Asset'!$AJ:$AJ,'Bridge Asset'!$BU:$BU,'Bridge Summary'!$B$7,'Bridge Asset'!$D:$D,'Bridge Summary'!$B10,'Bridge Asset'!$CR:$CR,'Bridge Summary'!H$5) | I10: =SUMIFS('Bridge Asset'!$AJ:$AJ,'Bridge Asset'!$BU:$BU,'Bridge Summary'!$B$7,'Bridge Asset'!$D:$D,'Bridge Summary'!$B10,'Bridge Asset'!$CR:$CR,'Bridge Summary'!I$5) | J10: =SUMIFS('Bridge Asset'!$AJ:$AJ,'Bridge Asset'!$BU:$BU,'Bridge Summary'!$B$7,'Bridge Asset'!$D:$D,'Bridge Summary'!$B10,'Bridge Asset'!$CR:$CR,'Bridge Summary'!J$5) | K10: =SUM($E10:$J10) | L10: =+$K10-$J10 | N10: =IFERROR(SUM($G10:$I10)/$L10,"N/A") | O10: =IFERROR(SUM($H10:$I10)/$L10,"N/A") | P10: =IFERROR($I10/$L10,"N/A") | Q10: =IFERROR($J10/$K10,"N/A")
B11: CAFL 2025-RRTL1 CV | C11: =COUNTIFS('Bridge Loan'!$AM:$AM,'Bridge Summary'!$B$7,'Bridge Loan'!$D:$D,'Bridge Summary'!$B11) | D11: =COUNTIFS('Bridge Asset'!$BU:$BU,'Bridge Summary'!$B$7,'Bridge Asset'!$D:$D,'Bridge Summary'!$B11) | E11: =SUMIFS('Bridge Asset'!$AJ:$AJ,'Bridge Asset'!$BU:$BU,'Bridge Summary'!$B$7,'Bridge Asset'!$D:$D,'Bridge Summary'!$B11,'Bridge Asset'!$CR:$CR,'Bridge Summary'!E$5) | F11: =SUMIFS('Bridge Asset'!$AJ:$AJ,'Bridge Asset'!$BU:$BU,'Bridge Summary'!$B$7,'Bridge Asset'!$D:$D,'Bridge Summary'!$B11,'Bridge Asset'!$CR:$CR,'Bridge Summary'!F$5) | G11: =SUMIFS('Bridge Asset'!$AJ:$AJ,'Bridge Asset'!$BU:$BU,'Bridge Summary'!$B$7,'Bridge Asset'!$D:$D,'Bridge Summary'!$B11,'Bridge Asset'!$CR:$CR,'Bridge Summary'!G$5) | H11: =SUMIFS('Bridge Asset'!$AJ:$AJ,'Bridge Asset'!$BU:$BU,'Bridge Summary'!$B$7,'Bridge Asset'!$D:$D,'Bridge Summary'!$B11,'Bridge Asset'!$CR:$CR,'Bridge Summary'!H$5) | I11: =SUMIFS('Bridge Asset'!$AJ:$AJ,'Bridge Asset'!$BU:$BU,'Bridge Summary'!$B$7,'Bridge Asset'!$D:$D,'Bridge Summary'!$B11,'Bridge Asset'!$CR:$CR,'Bridge Summary'!I$5) | J11: =SUMIFS('Bridge Asset'!$AJ:$AJ,'Bridge Asset'!$BU:$BU,'Bridge Summary'!$B$7,'Bridge Asset'!$D:$D,'Bridge Summary'!$B11,'Bridge Asset'!$CR:$CR,'Bridge Summary'!J$5) | K11: =SUM($E11:$J11) | L11: =+$K11-$J11 | N11: =IFERROR(SUM($G11:$I11)/$L11,"N/A") | O11: =IFERROR(SUM($H11:$I11)/$L11,"N/A") | P11: =IFERROR($I11/$L11,"N/A") | Q11: =IFERROR($J11/$K11,"N/A")
B12: CAFL 2025-RRTL2 CPP | C12: =COUNTIFS('Bridge Loan'!$AM:$AM,'Bridge Summary'!$B$7,'Bridge Loan'!$D:$D,'Bridge Summary'!$B12) | D12: =COUNTIFS('Bridge Asset'!$BU:$BU,'Bridge Summary'!$B$7,'Bridge Asset'!$D:$D,'Bridge Summary'!$B12) | E12: =SUMIFS('Bridge Asset'!$AJ:$AJ,'Bridge Asset'!$BU:$BU,'Bridge Summary'!$B$7,'Bridge Asset'!$D:$D,'Bridge Summary'!$B12,'Bridge Asset'!$CR:$CR,'Bridge Summary'!E$5) | F12: =SUMIFS('Bridge Asset'!$AJ:$AJ,'Bridge Asset'!$BU:$BU,'Bridge Summary'!$B$7,'Bridge Asset'!$D:$D,'Bridge Summary'!$B12,'Bridge Asset'!$CR:$CR,'Bridge Summary'!F$5) | G12: =SUMIFS('Bridge Asset'!$AJ:$AJ,'Bridge Asset'!$BU:$BU,'Bridge Summary'!$B$7,'Bridge Asset'!$D:$D,'Bridge Summary'!$B12,'Bridge Asset'!$CR:$CR,'Bridge Summary'!G$5) | H12: =SUMIFS('Bridge Asset'!$AJ:$AJ,'Bridge Asset'!$BU:$BU,'Bridge Summary'!$B$7,'Bridge Asset'!$D:$D,'Bridge Summary'!$B12,'Bridge Asset'!$CR:$CR,'Bridge Summary'!H$5) | I12: =SUMIFS('Bridge Asset'!$AJ:$AJ,'Bridge Asset'!$BU:$BU,'Bridge Summary'!$B$7,'Bridge Asset'!$D:$D,'Bridge Summary'!$B12,'Bridge Asset'!$CR:$CR,'Bridge Summary'!I$5) | J12: =SUMIFS('Bridge Asset'!$AJ:$AJ,'Bridge Asset'!$BU:$BU,'Bridge Summary'!$B$7,'Bridge Asset'!$D:$D,'Bridge Summary'!$B12,'Bridge Asset'!$CR:$CR,'Bridge Summary'!J$5) | K12: =SUM($E12:$J12) | L12: =+$K12-$J12 | N12: =IFERROR(SUM($G12:$I12)/$L12,"N/A") | O12: =IFERROR(SUM($H12:$I12)/$L12,"N/A") | P12: =IFERROR($I12/$L12,"N/A") | Q12: =IFERROR($J12/$K12,"N/A")
B13: CAFL 2025-RRTL2 CV | C13: =COUNTIFS('Bridge Loan'!$AM:$AM,'Bridge Summary'!$B$7,'Bridge Loan'!$D:$D,'Bridge Summary'!$B13) | D13: =COUNTIFS('Bridge Asset'!$BU:$BU,'Bridge Summary'!$B$7,'Bridge Asset'!$D:$D,'Bridge Summary'!$B13) | E13: =SUMIFS('Bridge Asset'!$AJ:$AJ,'Bridge Asset'!$BU:$BU,'Bridge Summary'!$B$7,'Bridge Asset'!$D:$D,'Bridge Summary'!$B13,'Bridge Asset'!$CR:$CR,'Bridge Summary'!E$5) | F13: =SUMIFS('Bridge Asset'!$AJ:$AJ,'Bridge Asset'!$BU:$BU,'Bridge Summary'!$B$7,'Bridge Asset'!$D:$D,'Bridge Summary'!$B13,'Bridge Asset'!$CR:$CR,'Bridge Summary'!F$5) | G13: =SUMIFS('Bridge Asset'!$AJ:$AJ,'Bridge Asset'!$BU:$BU,'Bridge Summary'!$B$7,'Bridge Asset'!$D:$D,'Bridge Summary'!$B13,'Bridge Asset'!$CR:$CR,'Bridge Summary'!G$5) | H13: =SUMIFS('Bridge Asset'!$AJ:$AJ,'Bridge Asset'!$BU:$BU,'Bridge Summary'!$B$7,'Bridge Asset'!$D:$D,'Bridge Summary'!$B13,'Bridge Asset'!$CR:$CR,'Bridge Summary'!H$5) | I13: =SUMIFS('Bridge Asset'!$AJ:$AJ,'Bridge Asset'!$BU:$BU,'Bridge Summary'!$B$7,'Bridge Asset'!$D:$D,'Bridge Summary'!$B13,'Bridge Asset'!$CR:$CR,'Bridge Summary'!I$5) | J13: =SUMIFS('Bridge Asset'!$AJ:$AJ,'Bridge Asset'!$BU:$BU,'Bridge Summary'!$B$7,'Bridge Asset'!$D:$D,'Bridge Summary'!$B13,'Bridge Asset'!$CR:$CR,'Bridge Summary'!J$5) | K13: =SUM($E13:$J13) | L13: =+$K13-$J13 | N13: =IFERROR(SUM($G13:$I13)/$L13,"N/A") | O13: =IFERROR(SUM($H13:$I13)/$L13,"N/A") | P13: =IFERROR($I13/$L13,"N/A") | Q13: =IFERROR($J13/$K13,"N/A")
B14: CAFL 2026-R1 CV | C14: =COUNTIFS('Bridge Loan'!$AM:$AM,'Bridge Summary'!$B$7,'Bridge Loan'!$D:$D,'Bridge Summary'!$B14) | D14: =COUNTIFS('Bridge Asset'!$BU:$BU,'Bridge Summary'!$B$7,'Bridge Asset'!$D:$D,'Bridge Summary'!$B14) | E14: =SUMIFS('Bridge Asset'!$AJ:$AJ,'Bridge Asset'!$BU:$BU,'Bridge Summary'!$B$7,'Bridge Asset'!$D:$D,'Bridge Summary'!$B14,'Bridge Asset'!$CR:$CR,'Bridge Summary'!E$5) | F14: =SUMIFS('Bridge Asset'!$AJ:$AJ,'Bridge Asset'!$BU:$BU,'Bridge Summary'!$B$7,'Bridge Asset'!$D:$D,'Bridge Summary'!$B14,'Bridge Asset'!$CR:$CR,'Bridge Summary'!F$5) | G14: =SUMIFS('Bridge Asset'!$AJ:$AJ,'Bridge Asset'!$BU:$BU,'Bridge Summary'!$B$7,'Bridge Asset'!$D:$D,'Bridge Summary'!$B14,'Bridge Asset'!$CR:$CR,'Bridge Summary'!G$5) | H14: =SUMIFS('Bridge Asset'!$AJ:$AJ,'Bridge Asset'!$BU:$BU,'Bridge Summary'!$B$7,'Bridge Asset'!$D:$D,'Bridge Summary'!$B14,'Bridge Asset'!$CR:$CR,'Bridge Summary'!H$5) | I14: =SUMIFS('Bridge Asset'!$AJ:$AJ,'Bridge Asset'!$BU:$BU,'Bridge Summary'!$B$7,'Bridge Asset'!$D:$D,'Bridge Summary'!$B14,'Bridge Asset'!$CR:$CR,'Bridge Summary'!I$5) | J14: =SUMIFS('Bridge Asset'!$AJ:$AJ,'Bridge Asset'!$BU:$BU,'Bridge Summary'!$B$7,'Bridge Asset'!$D:$D,'Bridge Summary'!$B14,'Bridge Asset'!$CR:$CR,'Bridge Summary'!J$5) | K14: =SUM($E14:$J14) | L14: =+$K14-$J14 | N14: =IFERROR(SUM($G14:$I14)/$L14,"N/A") | O14: =IFERROR(SUM($H14:$I14)/$L14,"N/A") | P14: =IFERROR($I14/$L14,"N/A") | Q14: =IFERROR($J14/$K14,"N/A")
B15: Mortgage Banking | C15: =COUNTIFS('Bridge Loan'!$AM:$AM,'Bridge Summary'!$B15) | D15: =COUNTIFS('Bridge Asset'!$BU:$BU,'Bridge Summary'!$B15) | E15: =SUMIFS('Bridge Asset'!$AJ:$AJ,'Bridge Asset'!$BU:$BU,'Bridge Summary'!$B15,'Bridge Asset'!$CR:$CR,'Bridge Summary'!E$5) | F15: =SUMIFS('Bridge Asset'!$AJ:$AJ,'Bridge Asset'!$BU:$BU,'Bridge Summary'!$B15,'Bridge Asset'!$CR:$CR,'Bridge Summary'!F$5) | G15: =SUMIFS('Bridge Asset'!$AJ:$AJ,'Bridge Asset'!$BU:$BU,'Bridge Summary'!$B15,'Bridge Asset'!$CR:$CR,'Bridge Summary'!G$5) | H15: =SUMIFS('Bridge Asset'!$AJ:$AJ,'Bridge Asset'!$BU:$BU,'Bridge Summary'!$B15,'Bridge Asset'!$CR:$CR,'Bridge Summary'!H$5) | I15: =SUMIFS('Bridge Asset'!$AJ:$AJ,'Bridge Asset'!$BU:$BU,'Bridge Summary'!$B15,'Bridge Asset'!$CR:$CR,'Bridge Summary'!I$5) | J15: =SUMIFS('Bridge Asset'!$AJ:$AJ,'Bridge Asset'!$BU:$BU,'Bridge Summary'!$B15,'Bridge Asset'!$CR:$CR,'Bridge Summary'!J$5) | K15: =SUM($E15:$J15) | L15: =+$K15-$J15 | N15: =IFERROR(SUM($G15:$I15)/$L15,"N/A") | O15: =IFERROR(SUM($H15:$I15)/$L15,"N/A") | P15: =IFERROR($I15/$L15,"N/A") | Q15: =IFERROR($J15/$K15,"N/A")
B16: SSP | C16: =COUNTIFS('Bridge Loan'!$AM:$AM,'Bridge Summary'!$B16) | D16: =COUNTIFS('Bridge Asset'!$BU:$BU,'Bridge Summary'!$B16) | E16: =SUMIFS('Bridge Asset'!$AJ:$AJ,'Bridge Asset'!$BU:$BU,'Bridge Summary'!$B16,'Bridge Asset'!$CR:$CR,'Bridge Summary'!E$5) | F16: =SUMIFS('Bridge Asset'!$AJ:$AJ,'Bridge Asset'!$BU:$BU,'Bridge Summary'!$B16,'Bridge Asset'!$CR:$CR,'Bridge Summary'!F$5) | G16: =SUMIFS('Bridge Asset'!$AJ:$AJ,'Bridge Asset'!$BU:$BU,'Bridge Summary'!$B16,'Bridge Asset'!$CR:$CR,'Bridge Summary'!G$5) | H16: =SUMIFS('Bridge Asset'!$AJ:$AJ,'Bridge Asset'!$BU:$BU,'Bridge Summary'!$B16,'Bridge Asset'!$CR:$CR,'Bridge Summary'!H$5) | I16: =SUMIFS('Bridge Asset'!$AJ:$AJ,'Bridge Asset'!$BU:$BU,'Bridge Summary'!$B16,'Bridge Asset'!$CR:$CR,'Bridge Summary'!I$5) | J16: =SUMIFS('Bridge Asset'!$AJ:$AJ,'Bridge Asset'!$BU:$BU,'Bridge Summary'!$B16,'Bridge Asset'!$CR:$CR,'Bridge Summary'!J$5) | K16: =SUM($E16:$J16) | L16: =+$K16-$J16 | N16: =IFERROR(SUM($G16:$I16)/$L16,"N/A") | O16: =IFERROR(SUM($H16:$I16)/$L16,"N/A") | P16: =IFERROR($I16/$L16,"N/A") | Q16: =IFERROR($J16/$K16,"N/A")
B17: CPP JV | C17: =COUNTIFS('Bridge Loan'!$AM:$AM,'Bridge Summary'!$B17) | D17: =COUNTIFS('Bridge Asset'!$BU:$BU,'Bridge Summary'!$B17) | E17: =SUMIFS('Bridge Asset'!$AJ:$AJ,'Bridge Asset'!$BU:$BU,'Bridge Summary'!$B17,'Bridge Asset'!$CR:$CR,'Bridge Summary'!E$5) | F17: =SUMIFS('Bridge Asset'!$AJ:$AJ,'Bridge Asset'!$BU:$BU,'Bridge Summary'!$B17,'Bridge Asset'!$CR:$CR,'Bridge Summary'!F$5) | G17: =SUMIFS('Bridge Asset'!$AJ:$AJ,'Bridge Asset'!$BU:$BU,'Bridge Summary'!$B17,'Bridge Asset'!$CR:$CR,'Bridge Summary'!G$5) | H17: =SUMIFS('Bridge Asset'!$AJ:$AJ,'Bridge Asset'!$BU:$BU,'Bridge Summary'!$B17,'Bridge Asset'!$CR:$CR,'Bridge Summary'!H$5) | I17: =SUMIFS('Bridge Asset'!$AJ:$AJ,'Bridge Asset'!$BU:$BU,'Bridge Summary'!$B17,'Bridge Asset'!$CR:$CR,'Bridge Summary'!I$5) | J17: =SUMIFS('Bridge Asset'!$AJ:$AJ,'Bridge Asset'!$BU:$BU,'Bridge Summary'!$B17,'Bridge Asset'!$CR:$CR,'Bridge Summary'!J$5) | K17: =SUM($E17:$J17) | L17: =+$K17-$J17 | N17: =IFERROR(SUM($G17:$I17)/$L17,"N/A") | O17: =IFERROR(SUM($H17:$I17)/$L17,"N/A") | P17: =IFERROR($I17/$L17,"N/A") | Q17: =IFERROR($J17/$K17,"N/A")
B18: Oaktree JV | C18: =COUNTIFS('Bridge Loan'!$AM:$AM,'Bridge Summary'!$B18) | D18: =COUNTIFS('Bridge Asset'!$BU:$BU,'Bridge Summary'!$B18) | E18: =SUMIFS('Bridge Asset'!$AJ:$AJ,'Bridge Asset'!$BU:$BU,'Bridge Summary'!$B18,'Bridge Asset'!$CR:$CR,'Bridge Summary'!E$5) | F18: =SUMIFS('Bridge Asset'!$AJ:$AJ,'Bridge Asset'!$BU:$BU,'Bridge Summary'!$B18,'Bridge Asset'!$CR:$CR,'Bridge Summary'!F$5) | G18: =SUMIFS('Bridge Asset'!$AJ:$AJ,'Bridge Asset'!$BU:$BU,'Bridge Summary'!$B18,'Bridge Asset'!$CR:$CR,'Bridge Summary'!G$5) | H18: =SUMIFS('Bridge Asset'!$AJ:$AJ,'Bridge Asset'!$BU:$BU,'Bridge Summary'!$B18,'Bridge Asset'!$CR:$CR,'Bridge Summary'!H$5) | I18: =SUMIFS('Bridge Asset'!$AJ:$AJ,'Bridge Asset'!$BU:$BU,'Bridge Summary'!$B18,'Bridge Asset'!$CR:$CR,'Bridge Summary'!I$5) | J18: =SUMIFS('Bridge Asset'!$AJ:$AJ,'Bridge Asset'!$BU:$BU,'Bridge Summary'!$B18,'Bridge Asset'!$CR:$CR,'Bridge Summary'!J$5) | K18: =SUM($E18:$J18) | L18: =+$K18-$J18 | N18: =IFERROR(SUM($G18:$I18)/$L18,"N/A") | O18: =IFERROR(SUM($H18:$I18)/$L18,"N/A") | P18: =IFERROR($I18/$L18,"N/A") | Q18: =IFERROR($J18/$K18,"N/A")
B19: Sold Servicing Retained | C19: =COUNTIFS('Bridge Loan'!$AM:$AM,'Bridge Summary'!$B19) | D19: =COUNTIFS('Bridge Asset'!$BU:$BU,'Bridge Summary'!$B19) | E19: =SUMIFS('Bridge Asset'!$AJ:$AJ,'Bridge Asset'!$BU:$BU,'Bridge Summary'!$B19,'Bridge Asset'!$CR:$CR,'Bridge Summary'!E$5) | F19: =SUMIFS('Bridge Asset'!$AJ:$AJ,'Bridge Asset'!$BU:$BU,'Bridge Summary'!$B19,'Bridge Asset'!$CR:$CR,'Bridge Summary'!F$5) | G19: =SUMIFS('Bridge Asset'!$AJ:$AJ,'Bridge Asset'!$BU:$BU,'Bridge Summary'!$B19,'Bridge Asset'!$CR:$CR,'Bridge Summary'!G$5) | H19: =SUMIFS('Bridge Asset'!$AJ:$AJ,'Bridge Asset'!$BU:$BU,'Bridge Summary'!$B19,'Bridge Asset'!$CR:$CR,'Bridge Summary'!H$5) | I19: =SUMIFS('Bridge Asset'!$AJ:$AJ,'Bridge Asset'!$BU:$BU,'Bridge Summary'!$B19,'Bridge Asset'!$CR:$CR,'Bridge Summary'!I$5) | J19: =SUMIFS('Bridge Asset'!$AJ:$AJ,'Bridge Asset'!$BU:$BU,'Bridge Summary'!$B19,'Bridge Asset'!$CR:$CR,'Bridge Summary'!J$5) | K19: =SUM($E19:$J19) | L19: =+$K19-$J19 | N19: =IFERROR(SUM($G19:$I19)/$L19,"N/A") | O19: =IFERROR(SUM($H19:$I19)/$L19,"N/A") | P19: =IFERROR($I19/$L19,"N/A") | Q19: =IFERROR($J19/$K19,"N/A")
B20: Total Bridge | C20: =+C$6+C$7+C$15+C$16+C$17+C$18+C$19 | D20: =+D$6+D$7+D$15+D$16+D$17+D$18+D$19 | E20: =+E$6+E$7+E$15+E$16+E$17+E$18+E$19 | F20: =+F$6+F$7+F$15+F$16+F$17+F$18+F$19 | G20: =+G$6+G$7+G$15+G$16+G$17+G$18+G$19 | H20: =+H$6+H$7+H$15+H$16+H$17+H$18+H$19 | I20: =+I$6+I$7+I$15+I$16+I$17+I$18+I$19 | J20: =+J$6+J$7+J$15+J$16+J$17+J$18+J$19 | ... L20: =+L$6+L$7+L$15+L$16+L$17+L$18+L$19 | N20: =IFERROR(SUM($G20:$I20)/$L20,"N/A") | O20: =IFERROR(SUM($H20:$I20)/$L20,"N/A") | P20: =IFERROR($I20/$L20,"N/A") | Q20: =IFERROR($J20/$K20,"N/A")
B21: Total Bridge (Ex. Sold) | C21: =+C$20-C$19 | D21: =+D$20-D$19 | E21: =+E$20-E$19 | F21: =+F$20-F$19 | G21: =+G$20-G$19 | H21: =+H$20-H$19 | I21: =+I$20-I$19 | J21: =+J$20-J$19 | ... L21: =+L$20-L$19 | N21: =IFERROR(SUM($G21:$I21)/$L21,"N/A") | O21: =IFERROR(SUM($H21:$I21)/$L21,"N/A") | P21: =IFERROR($I21/$L21,"N/A") | Q21: =IFERROR($J21/$K21,"N/A")
B23: Legacy Bridge | C23: =+C$6 | D23: =+D$6 | E23: =+E$6 | F23: =+F$6 | G23: =+G$6 | H23: =+H$6 | I23: =+I$6 | J23: =+J$6 | K23: =SUM($E23:$J23) | L23: =+$K23-$J23 | N23: =IFERROR(SUM($G23:$I23)/$L23,"N/A") | O23: =IFERROR(SUM($H23:$I23)/$L23,"N/A") | P23: =IFERROR($I23/$L23,"N/A") | Q23: =IFERROR($J23/$K23,"N/A")
B24: Non-Legacy Bridge | C24: =+C$7+C$15 | D24: =+D$7+D$15 | E24: =+E$7+E$15 | F24: =+F$7+F$15 | G24: =+G$7+G$15 | H24: =+H$7+H$15 | I24: =+I$7+I$15 | J24: =+J$7+J$15 | K24: =SUM($E24:$J24) | L24: =+$K24-$J24 | N24: =IFERROR(SUM($G24:$I24)/$L24,"N/A") | O24: =IFERROR(SUM($H24:$I24)/$L24,"N/A") | P24: =IFERROR($I24/$L24,"N/A") | Q24: =IFERROR($J24/$K24,"N/A")
B25: Balance Sheet Bridge | C25: =SUM(C$23:C$24) | D25: =SUM(D$23:D$24) | E25: =SUM(E$23:E$24) | F25: =SUM(F$23:F$24) | G25: =SUM(G$23:G$24) | H25: =SUM(H$23:H$24) | I25: =SUM(I$23:I$24) | J25: =SUM(J$23:J$24) | K25: =SUM($E25:$J25) | L25: =+$K25-$J25 | N25: =IFERROR(SUM($G25:$I25)/$L25,"N/A") | O25: =IFERROR(SUM($H25:$I25)/$L25,"N/A") | P25: =IFERROR($I25/$L25,"N/A") | Q25: =IFERROR($J25/$K25,"N/A")
B28: Summary by Strategy:
C29: =+C$5 | D29: =+D$5 | E29: =+E$5 | F29: =+F$5 | G29: =+G$5 | H29: =+H$5 | I29: =+I$5 | J29: =+J$5 | ... L29: =+L$5 | N29: =+N$5 | O29: =+O$5 | P29: =+P$5 | Q29: =+Q$5
B30: Renovate / Build to Rent | C30: =COUNTIFS('Bridge Loan'!$AS:$AS,'Bridge Summary'!$B30) | D30: =COUNTIFS('Bridge Asset'!$BZ:$BZ,'Bridge Summary'!$B30) | E30: =SUMIFS('Bridge Asset'!$AJ:$AJ,'Bridge Asset'!$BZ:$BZ,'Bridge Summary'!$B30,'Bridge Asset'!$CR:$CR,'Bridge Summary'!E$29) | F30: =SUMIFS('Bridge Asset'!$AJ:$AJ,'Bridge Asset'!$BZ:$BZ,'Bridge Summary'!$B30,'Bridge Asset'!$CR:$CR,'Bridge Summary'!F$29) | G30: =SUMIFS('Bridge Asset'!$AJ:$AJ,'Bridge Asset'!$BZ:$BZ,'Bridge Summary'!$B30,'Bridge Asset'!$CR:$CR,'Bridge Summary'!G$29) | H30: =SUMIFS('Bridge Asset'!$AJ:$AJ,'Bridge Asset'!$BZ:$BZ,'Bridge Summary'!$B30,'Bridge Asset'!$CR:$CR,'Bridge Summary'!H$29) | I30: =SUMIFS('Bridge Asset'!$AJ:$AJ,'Bridge Asset'!$BZ:$BZ,'Bridge Summary'!$B30,'Bridge Asset'!$CR:$CR,'Bridge Summary'!I$29) | J30: =SUMIFS('Bridge Asset'!$AJ:$AJ,'Bridge Asset'!$BZ:$BZ,'Bridge Summary'!$B30,'Bridge Asset'!$CR:$CR,'Bridge Summary'!J$29) | K30: =SUM($E30:$J30) | L30: =+$K30-$J30 | N30: =IFERROR(SUM($G30:$I30)/$L30,"N/A") | O30: =IFERROR(SUM($H30:$I30)/$L30,"N/A") | P30: =IFERROR($I30/$L30,"N/A") | Q30: =IFERROR($J30/$K30,"N/A")
B31: Single Asset Bridge | C31: =COUNTIFS('Bridge Loan'!$AS:$AS,'Bridge Summary'!$B31) | D31: =COUNTIFS('Bridge Asset'!$BZ:$BZ,'Bridge Summary'!$B31) | E31: =SUMIFS('Bridge Asset'!$AJ:$AJ,'Bridge Asset'!$BZ:$BZ,'Bridge Summary'!$B31,'Bridge Asset'!$CR:$CR,'Bridge Summary'!E$29) | F31: =SUMIFS('Bridge Asset'!$AJ:$AJ,'Bridge Asset'!$BZ:$BZ,'Bridge Summary'!$B31,'Bridge Asset'!$CR:$CR,'Bridge Summary'!F$29) | G31: =SUMIFS('Bridge Asset'!$AJ:$AJ,'Bridge Asset'!$BZ:$BZ,'Bridge Summary'!$B31,'Bridge Asset'!$CR:$CR,'Bridge Summary'!G$29) | H31: =SUMIFS('Bridge Asset'!$AJ:$AJ,'Bridge Asset'!$BZ:$BZ,'Bridge Summary'!$B31,'Bridge Asset'!$CR:$CR,'Bridge Summary'!H$29) | I31: =SUMIFS('Bridge Asset'!$AJ:$AJ,'Bridge Asset'!$BZ:$BZ,'Bridge Summary'!$B31,'Bridge Asset'!$CR:$CR,'Bridge Summary'!I$29) | J31: =SUMIFS('Bridge Asset'!$AJ:$AJ,'Bridge Asset'!$BZ:$BZ,'Bridge Summary'!$B31,'Bridge Asset'!$CR:$CR,'Bridge Summary'!J$29) | K31: =SUM($E31:$J31) | L31: =+$K31-$J31 | N31: =IFERROR(SUM($G31:$I31)/$L31,"N/A") | O31: =IFERROR(SUM($H31:$I31)/$L31,"N/A") | P31: =IFERROR($I31/$L31,"N/A") | Q31: =IFERROR($J31/$K31,"N/A")
B32: Multifamily | C32: =COUNTIFS('Bridge Loan'!$AS:$AS,'Bridge Summary'!$B32) | D32: =COUNTIFS('Bridge Asset'!$BZ:$BZ,'Bridge Summary'!$B32) | E32: =SUMIFS('Bridge Asset'!$AJ:$AJ,'Bridge Asset'!$BZ:$BZ,'Bridge Summary'!$B32,'Bridge Asset'!$CR:$CR,'Bridge Summary'!E$29) | F32: =SUMIFS('Bridge Asset'!$AJ:$AJ,'Bridge Asset'!$BZ:$BZ,'Bridge Summary'!$B32,'Bridge Asset'!$CR:$CR,'Bridge Summary'!F$29) | G32: =SUMIFS('Bridge Asset'!$AJ:$AJ,'Bridge Asset'!$BZ:$BZ,'Bridge Summary'!$B32,'Bridge Asset'!$CR:$CR,'Bridge Summary'!G$29) | H32: =SUMIFS('Bridge Asset'!$AJ:$AJ,'Bridge Asset'!$BZ:$BZ,'Bridge Summary'!$B32,'Bridge Asset'!$CR:$CR,'Bridge Summary'!H$29) | I32: =SUMIFS('Bridge Asset'!$AJ:$AJ,'Bridge Asset'!$BZ:$BZ,'Bridge Summary'!$B32,'Bridge Asset'!$CR:$CR,'Bridge Summary'!I$29) | J32: =SUMIFS('Bridge Asset'!$AJ:$AJ,'Bridge Asset'!$BZ:$BZ,'Bridge Summary'!$B32,'Bridge Asset'!$CR:$CR,'Bridge Summary'!J$29) | K32: =SUM($E32:$J32) | L32: =+$K32-$J32 | N32: =IFERROR(SUM($G32:$I32)/$L32,"N/A") | O32: =IFERROR(SUM($H32:$I32)/$L32,"N/A") | P32: =IFERROR($I32/$L32,"N/A") | Q32: =IFERROR($J32/$K32,"N/A")
B33: Other | C33: =COUNTIFS('Bridge Loan'!$AS:$AS,'Bridge Summary'!$B33) | D33: =COUNTIFS('Bridge Asset'!$BZ:$BZ,'Bridge Summary'!$B33) | E33: =SUMIFS('Bridge Asset'!$AJ:$AJ,'Bridge Asset'!$BZ:$BZ,'Bridge Summary'!$B33,'Bridge Asset'!$CR:$CR,'Bridge Summary'!E$29) | F33: =SUMIFS('Bridge Asset'!$AJ:$AJ,'Bridge Asset'!$BZ:$BZ,'Bridge Summary'!$B33,'Bridge Asset'!$CR:$CR,'Bridge Summary'!F$29) | G33: =SUMIFS('Bridge Asset'!$AJ:$AJ,'Bridge Asset'!$BZ:$BZ,'Bridge Summary'!$B33,'Bridge Asset'!$CR:$CR,'Bridge Summary'!G$29) | H33: =SUMIFS('Bridge Asset'!$AJ:$AJ,'Bridge Asset'!$BZ:$BZ,'Bridge Summary'!$B33,'Bridge Asset'!$CR:$CR,'Bridge Summary'!H$29) | I33: =SUMIFS('Bridge Asset'!$AJ:$AJ,'Bridge Asset'!$BZ:$BZ,'Bridge Summary'!$B33,'Bridge Asset'!$CR:$CR,'Bridge Summary'!I$29) | J33: =SUMIFS('Bridge Asset'!$AJ:$AJ,'Bridge Asset'!$BZ:$BZ,'Bridge Summary'!$B33,'Bridge Asset'!$CR:$CR,'Bridge Summary'!J$29) | K33: =SUM($E33:$J33) | L33: =+$K33-$J33 | N33: =IFERROR(SUM($G33:$I33)/$L33,"N/A") | O33: =IFERROR(SUM($H33:$I33)/$L33,"N/A") | P33: =IFERROR($I33/$L33,"N/A") | Q33: =IFERROR($J33/$K33,"N/A")
B34: Sold | C34: =COUNTIFS('Bridge Loan'!$AS:$AS,'Bridge Summary'!$B34) | D34: =COUNTIFS('Bridge Asset'!$BZ:$BZ,'Bridge Summary'!$B34) | E34: =SUMIFS('Bridge Asset'!$AJ:$AJ,'Bridge Asset'!$BZ:$BZ,'Bridge Summary'!$B34,'Bridge Asset'!$CR:$CR,'Bridge Summary'!E$29) | F34: =SUMIFS('Bridge Asset'!$AJ:$AJ,'Bridge Asset'!$BZ:$BZ,'Bridge Summary'!$B34,'Bridge Asset'!$CR:$CR,'Bridge Summary'!F$29) | G34: =SUMIFS('Bridge Asset'!$AJ:$AJ,'Bridge Asset'!$BZ:$BZ,'Bridge Summary'!$B34,'Bridge Asset'!$CR:$CR,'Bridge Summary'!G$29) | H34: =SUMIFS('Bridge Asset'!$AJ:$AJ,'Bridge Asset'!$BZ:$BZ,'Bridge Summary'!$B34,'Bridge Asset'!$CR:$CR,'Bridge Summary'!H$29) | I34: =SUMIFS('Bridge Asset'!$AJ:$AJ,'Bridge Asset'!$BZ:$BZ,'Bridge Summary'!$B34,'Bridge Asset'!$CR:$CR,'Bridge Summary'!I$29) | J34: =SUMIFS('Bridge Asset'!$AJ:$AJ,'Bridge Asset'!$BZ:$BZ,'Bridge Summary'!$B34,'Bridge Asset'!$CR:$CR,'Bridge Summary'!J$29) | K34: =SUM($E34:$J34) | L34: =+$K34-$J34 | N34: =IFERROR(SUM($G34:$I34)/$L34,"N/A") | O34: =IFERROR(SUM($H34:$I34)/$L34,"N/A") | P34: =IFERROR($I34/$L34,"N/A") | Q34: =IFERROR($J34/$K34,"N/A")
B35: Total Bridge | C35: =SUM(C$30:C$34) | D35: =SUM(D$30:D$34) | E35: =SUM(E$30:E$34) | F35: =SUM(F$30:F$34) | G35: =SUM(G$30:G$34) | H35: =SUM(H$30:H$34) | I35: =SUM(I$30:I$34) | J35: =SUM(J$30:J$34) | K35: =SUM($E35:$J35) | L35: =+$K35-$J35 | N35: =IFERROR(SUM($G35:$I35)/$L35,"N/A") | O35: =IFERROR(SUM($H35:$I35)/$L35,"N/A") | P35: =IFERROR($I35/$L35,"N/A") | Q35: =IFERROR($J35/$K35,"N/A")
B36: Total Bridge (Ex. Sold) | C36: =+C$35-C$34 | D36: =+D$35-D$34 | E36: =+E$35-E$34 | F36: =+F$35-F$34 | G36: =+G$35-G$34 | H36: =+H$35-H$34 | I36: =+I$35-I$34 | J36: =+J$35-J$34 | K36: =SUM($E36:$J36) | L36: =+$K36-$J36 | N36: =IFERROR(SUM($G36:$I36)/$L36,"N/A") | O36: =IFERROR(SUM($H36:$I36)/$L36,"N/A") | P36: =IFERROR($I36/$L36,"N/A") | Q36: =IFERROR($J36/$K36,"N/A")
B39: Summary by Product:
C40: =+C$29 | D40: =+D$29 | E40: =+E$29 | F40: =+F$29 | G40: =+G$29 | H40: =+H$29 | I40: =+I$29 | J40: =+J$29 | ... L40: =+L$29 | N40: =+N$29 | O40: =+O$29 | P40: =+P$29 | Q40: =+Q$29
B41: Single Asset Bridge | C41: =COUNTIFS('Bridge Loan'!$AN:$AN,'Bridge Summary'!$B41) | D41: =COUNTIFS('Bridge Asset'!$CL:$CL,'Bridge Summary'!$B41) | E41: =SUMIFS('Bridge Asset'!$AJ:$AJ,'Bridge Asset'!$CL:$CL,'Bridge Summary'!$B41,'Bridge Asset'!$CR:$CR,'Bridge Summary'!E$40) | F41: =SUMIFS('Bridge Asset'!$AJ:$AJ,'Bridge Asset'!$CL:$CL,'Bridge Summary'!$B41,'Bridge Asset'!$CR:$CR,'Bridge Summary'!F$40) | G41: =SUMIFS('Bridge Asset'!$AJ:$AJ,'Bridge Asset'!$CL:$CL,'Bridge Summary'!$B41,'Bridge Asset'!$CR:$CR,'Bridge Summary'!G$40) | H41: =SUMIFS('Bridge Asset'!$AJ:$AJ,'Bridge Asset'!$CL:$CL,'Bridge Summary'!$B41,'Bridge Asset'!$CR:$CR,'Bridge Summary'!H$40) | I41: =SUMIFS('Bridge Asset'!$AJ:$AJ,'Bridge Asset'!$CL:$CL,'Bridge Summary'!$B41,'Bridge Asset'!$CR:$CR,'Bridge Summary'!I$40) | J41: =SUMIFS('Bridge Asset'!$AJ:$AJ,'Bridge Asset'!$CL:$CL,'Bridge Summary'!$B41,'Bridge Asset'!$CR:$CR,'Bridge Summary'!J$40) | K41: =SUM($E41:$J41) | L41: =+$K41-$J41 | N41: =IFERROR(SUM($G41:$I41)/$L41,"N/A") | O41: =IFERROR(SUM($H41:$I41)/$L41,"N/A") | P41: =IFERROR($I41/$L41,"N/A") | Q41: =IFERROR($J41/$K41,"N/A")
B42: Single Asset Bridge (Ex. Sold) | C42: =+C$41-C$34 | D42: =+D$41-D$34 | E42: =+E$41-E$34 | F42: =+F$41-F$34 | G42: =+G$41-G$34 | H42: =+H$41-H$34 | I42: =+I$41-I$34 | J42: =+J$41-J$34 | ... L42: =+L$41-L$34 | N42: =IFERROR(SUM($G42:$I42)/$L42,"N/A") | O42: =IFERROR(SUM($H42:$I42)/$L42,"N/A") | P42: =IFERROR($I42/$L42,"N/A") | Q42: =IFERROR($J42/$K42,"N/A")
B43: Credit Line | C43: =COUNTIFS('Bridge Loan'!$AN:$AN,'Bridge Summary'!$B43) | D43: =COUNTIFS('Bridge Asset'!$CL:$CL,'Bridge Summary'!$B43) | E43: =SUMIFS('Bridge Asset'!$AJ:$AJ,'Bridge Asset'!$CL:$CL,'Bridge Summary'!$B43,'Bridge Asset'!$CR:$CR,'Bridge Summary'!E$40) | F43: =SUMIFS('Bridge Asset'!$AJ:$AJ,'Bridge Asset'!$CL:$CL,'Bridge Summary'!$B43,'Bridge Asset'!$CR:$CR,'Bridge Summary'!F$40) | G43: =SUMIFS('Bridge Asset'!$AJ:$AJ,'Bridge Asset'!$CL:$CL,'Bridge Summary'!$B43,'Bridge Asset'!$CR:$CR,'Bridge Summary'!G$40) | H43: =SUMIFS('Bridge Asset'!$AJ:$AJ,'Bridge Asset'!$CL:$CL,'Bridge Summary'!$B43,'Bridge Asset'!$CR:$CR,'Bridge Summary'!H$40) | I43: =SUMIFS('Bridge Asset'!$AJ:$AJ,'Bridge Asset'!$CL:$CL,'Bridge Summary'!$B43,'Bridge Asset'!$CR:$CR,'Bridge Summary'!I$40) | J43: =SUMIFS('Bridge Asset'!$AJ:$AJ,'Bridge Asset'!$CL:$CL,'Bridge Summary'!$B43,'Bridge Asset'!$CR:$CR,'Bridge Summary'!J$40) | K43: =SUM($E43:$J43) | L43: =+$K43-$J43 | N43: =IFERROR(SUM($G43:$I43)/$L43,"N/A") | O43: =IFERROR(SUM($H43:$I43)/$L43,"N/A") | P43: =IFERROR($I43/$L43,"N/A") | Q43: =IFERROR($J43/$K43,"N/A")
B44: Multifamily/CRE | C44: =COUNTIFS('Bridge Loan'!$AN:$AN,'Bridge Summary'!$B44) | D44: =COUNTIFS('Bridge Asset'!$CL:$CL,'Bridge Summary'!$B44) | E44: =SUMIFS('Bridge Asset'!$AJ:$AJ,'Bridge Asset'!$CL:$CL,'Bridge Summary'!$B44,'Bridge Asset'!$CR:$CR,'Bridge Summary'!E$40) | F44: =SUMIFS('Bridge Asset'!$AJ:$AJ,'Bridge Asset'!$CL:$CL,'Bridge Summary'!$B44,'Bridge Asset'!$CR:$CR,'Bridge Summary'!F$40) | G44: =SUMIFS('Bridge Asset'!$AJ:$AJ,'Bridge Asset'!$CL:$CL,'Bridge Summary'!$B44,'Bridge Asset'!$CR:$CR,'Bridge Summary'!G$40) | H44: =SUMIFS('Bridge Asset'!$AJ:$AJ,'Bridge Asset'!$CL:$CL,'Bridge Summary'!$B44,'Bridge Asset'!$CR:$CR,'Bridge Summary'!H$40) | I44: =SUMIFS('Bridge Asset'!$AJ:$AJ,'Bridge Asset'!$CL:$CL,'Bridge Summary'!$B44,'Bridge Asset'!$CR:$CR,'Bridge Summary'!I$40) | J44: =SUMIFS('Bridge Asset'!$AJ:$AJ,'Bridge Asset'!$CL:$CL,'Bridge Summary'!$B44,'Bridge Asset'!$CR:$CR,'Bridge Summary'!J$40) | K44: =SUM($E44:$J44) | L44: =+$K44-$J44 | N44: =IFERROR(SUM($G44:$I44)/$L44,"N/A") | O44: =IFERROR(SUM($H44:$I44)/$L44,"N/A") | P44: =IFERROR($I44/$L44,"N/A") | Q44: =IFERROR($J44/$K44,"N/A")
B45: Build to Rent | C45: =COUNTIFS('Bridge Loan'!$AN:$AN,'Bridge Summary'!$B45) | D45: =COUNTIFS('Bridge Asset'!$CL:$CL,'Bridge Summary'!$B45) | E45: =SUMIFS('Bridge Asset'!$AJ:$AJ,'Bridge Asset'!$CL:$CL,'Bridge Summary'!$B45,'Bridge Asset'!$CR:$CR,'Bridge Summary'!E$40) | F45: =SUMIFS('Bridge Asset'!$AJ:$AJ,'Bridge Asset'!$CL:$CL,'Bridge Summary'!$B45,'Bridge Asset'!$CR:$CR,'Bridge Summary'!F$40) | G45: =SUMIFS('Bridge Asset'!$AJ:$AJ,'Bridge Asset'!$CL:$CL,'Bridge Summary'!$B45,'Bridge Asset'!$CR:$CR,'Bridge Summary'!G$40) | H45: =SUMIFS('Bridge Asset'!$AJ:$AJ,'Bridge Asset'!$CL:$CL,'Bridge Summary'!$B45,'Bridge Asset'!$CR:$CR,'Bridge Summary'!H$40) | I45: =SUMIFS('Bridge Asset'!$AJ:$AJ,'Bridge Asset'!$CL:$CL,'Bridge Summary'!$B45,'Bridge Asset'!$CR:$CR,'Bridge Summary'!I$40) | J45: =SUMIFS('Bridge Asset'!$AJ:$AJ,'Bridge Asset'!$CL:$CL,'Bridge Summary'!$B45,'Bridge Asset'!$CR:$CR,'Bridge Summary'!J$40) | K45: =SUM($E45:$J45) | L45: =+$K45-$J45 | N45: =IFERROR(SUM($G45:$I45)/$L45,"N/A") | O45: =IFERROR(SUM($H45:$I45)/$L45,"N/A") | P45: =IFERROR($I45/$L45,"N/A") | Q45: =IFERROR($J45/$K45,"N/A")
B46: 5A Bridge | C46: =COUNTIFS('Bridge Loan'!$AN:$AN,'Bridge Summary'!$B46) | D46: =COUNTIFS('Bridge Asset'!$CL:$CL,'Bridge Summary'!$B46) | E46: =SUMIFS('Bridge Asset'!$AJ:$AJ,'Bridge Asset'!$CL:$CL,'Bridge Summary'!$B46,'Bridge Asset'!$CR:$CR,'Bridge Summary'!E$40) | F46: =SUMIFS('Bridge Asset'!$AJ:$AJ,'Bridge Asset'!$CL:$CL,'Bridge Summary'!$B46,'Bridge Asset'!$CR:$CR,'Bridge Summary'!F$40) | G46: =SUMIFS('Bridge Asset'!$AJ:$AJ,'Bridge Asset'!$CL:$CL,'Bridge Summary'!$B46,'Bridge Asset'!$CR:$CR,'Bridge Summary'!G$40) | H46: =SUMIFS('Bridge Asset'!$AJ:$AJ,'Bridge Asset'!$CL:$CL,'Bridge Summary'!$B46,'Bridge Asset'!$CR:$CR,'Bridge Summary'!H$40) | I46: =SUMIFS('Bridge Asset'!$AJ:$AJ,'Bridge Asset'!$CL:$CL,'Bridge Summary'!$B46,'Bridge Asset'!$CR:$CR,'Bridge Summary'!I$40) | J46: =SUMIFS('Bridge Asset'!$AJ:$AJ,'Bridge Asset'!$CL:$CL,'Bridge Summary'!$B46,'Bridge Asset'!$CR:$CR,'Bridge Summary'!J$40) | K46: =SUM($E46:$J46) | L46: =+$K46-$J46 | N46: =IFERROR(SUM($G46:$I46)/$L46,"N/A") | O46: =IFERROR(SUM($H46:$I46)/$L46,"N/A") | P46: =IFERROR($I46/$L46,"N/A") | Q46: =IFERROR($J46/$K46,"N/A")
B47: Purchased Bridge | C47: =COUNTIFS('Bridge Loan'!$AN:$AN,'Bridge Summary'!$B47) | D47: =COUNTIFS('Bridge Asset'!$CL:$CL,'Bridge Summary'!$B47) | E47: =SUMIFS('Bridge Asset'!$AJ:$AJ,'Bridge Asset'!$CL:$CL,'Bridge Summary'!$B47,'Bridge Asset'!$CR:$CR,'Bridge Summary'!E$40) | F47: =SUMIFS('Bridge Asset'!$AJ:$AJ,'Bridge Asset'!$CL:$CL,'Bridge Summary'!$B47,'Bridge Asset'!$CR:$CR,'Bridge Summary'!F$40) | G47: =SUMIFS('Bridge Asset'!$AJ:$AJ,'Bridge Asset'!$CL:$CL,'Bridge Summary'!$B47,'Bridge Asset'!$CR:$CR,'Bridge Summary'!G$40) | H47: =SUMIFS('Bridge Asset'!$AJ:$AJ,'Bridge Asset'!$CL:$CL,'Bridge Summary'!$B47,'Bridge Asset'!$CR:$CR,'Bridge Summary'!H$40) | I47: =SUMIFS('Bridge Asset'!$AJ:$AJ,'Bridge Asset'!$CL:$CL,'Bridge Summary'!$B47,'Bridge Asset'!$CR:$CR,'Bridge Summary'!I$40) | J47: =SUMIFS('Bridge Asset'!$AJ:$AJ,'Bridge Asset'!$CL:$CL,'Bridge Summary'!$B47,'Bridge Asset'!$CR:$CR,'Bridge Summary'!J$40) | K47: =SUM($E47:$J47) | L47: =+$K47-$J47 | N47: =IFERROR(SUM($G47:$I47)/$L47,"N/A") | O47: =IFERROR(SUM($H47:$I47)/$L47,"N/A") | P47: =IFERROR($I47/$L47,"N/A") | Q47: =IFERROR($J47/$K47,"N/A")
...

Sheet Term Summary
B2: Term Portfolio
B4: Summary by Segment:
C5: Loan Count | D5: Asset Count | E5: Current | F5: DQ 1-29 | G5: DQ 30-59 | H5: DQ 60-89 | I5: DQ 90+ | J5: REO | K5: Total | L5: Total Ex. REO | N5: DQ 30+ % | O5: DQ 60+ % | P5: DQ 90+ % | Q5: REO %
B6: Legacy | C6: =COUNTIFS('Term Loan'!$K:$K,'Term Summary'!$B6) | D6: =COUNTIFS('Term Asset'!$E:$E,'Term Summary'!$B6) | E6: =SUMIFS('Term Loan'!$P:$P,'Term Loan'!$K:$K,'Term Summary'!$B6,'Term Loan'!$V:$V,'Term Summary'!E$5) | F6: =SUMIFS('Term Loan'!$P:$P,'Term Loan'!$K:$K,'Term Summary'!$B6,'Term Loan'!$V:$V,'Term Summary'!F$5) | G6: =SUMIFS('Term Loan'!$P:$P,'Term Loan'!$K:$K,'Term Summary'!$B6,'Term Loan'!$V:$V,'Term Summary'!G$5) | H6: =SUMIFS('Term Loan'!$P:$P,'Term Loan'!$K:$K,'Term Summary'!$B6,'Term Loan'!$V:$V,'Term Summary'!H$5) | I6: =SUMIFS('Term Loan'!$P:$P,'Term Loan'!$K:$K,'Term Summary'!$B6,'Term Loan'!$V:$V,'Term Summary'!I$5) | J6: =SUMIFS('Term Loan'!$P:$P,'Term Loan'!$K:$K,'Term Summary'!$B6,'Term Loan'!$V:$V,'Term Summary'!J$5) | K6: =SUM($E6:$J6) | L6: =+$K6-$J6 | N6: =IFERROR(SUM($G6:$I6)/$L6,"N/A") | O6: =IFERROR(SUM($H6:$I6)/$L6,"N/A") | P6: =IFERROR($I6/$L6,"N/A") | Q6: =IFERROR($J6/$K6,"N/A")
B7: Securitized Term | C7: =SUM(C$8:C$24) | D7: =SUM(D$8:D$24) | E7: =SUM(E$8:E$24) | F7: =SUM(F$8:F$24) | G7: =SUM(G$8:G$24) | H7: =SUM(H$8:H$24) | I7: =SUM(I$8:I$24) | J7: =SUM(J$8:J$24) | K7: =SUM($E7:$J7) | L7: =+$K7-$J7 | N7: =IFERROR(SUM($G7:$I7)/$L7,"N/A") | O7: =IFERROR(SUM($H7:$I7)/$L7,"N/A") | P7: =IFERROR($I7/$L7,"N/A") | Q7: =IFERROR($J7/$K7,"N/A")
B8: 2017-2 | C8: =COUNTIFS('Term Loan'!$K:$K,'Term Summary'!$B$7,'Term Loan'!$L:$L,'Term Summary'!$B8) | D8: =COUNTIFS('Term Asset'!$E:$E,'Term Summary'!$B$7,'Term Asset'!$F:$F,'Term Summary'!$B8) | E8: =SUMIFS('Term Loan'!$P:$P,'Term Loan'!$K:$K,'Term Summary'!$B$7,'Term Loan'!$L:$L,'Term Summary'!$B8,'Term Loan'!$V:$V,'Term Summary'!E$5) | F8: =SUMIFS('Term Loan'!$P:$P,'Term Loan'!$K:$K,'Term Summary'!$B$7,'Term Loan'!$L:$L,'Term Summary'!$B8,'Term Loan'!$V:$V,'Term Summary'!F$5) | G8: =SUMIFS('Term Loan'!$P:$P,'Term Loan'!$K:$K,'Term Summary'!$B$7,'Term Loan'!$L:$L,'Term Summary'!$B8,'Term Loan'!$V:$V,'Term Summary'!G$5) | H8: =SUMIFS('Term Loan'!$P:$P,'Term Loan'!$K:$K,'Term Summary'!$B$7,'Term Loan'!$L:$L,'Term Summary'!$B8,'Term Loan'!$V:$V,'Term Summary'!H$5) | I8: =SUMIFS('Term Loan'!$P:$P,'Term Loan'!$K:$K,'Term Summary'!$B$7,'Term Loan'!$L:$L,'Term Summary'!$B8,'Term Loan'!$V:$V,'Term Summary'!I$5) | J8: =SUMIFS('Term Loan'!$P:$P,'Term Loan'!$K:$K,'Term Summary'!$B$7,'Term Loan'!$L:$L,'Term Summary'!$B8,'Term Loan'!$V:$V,'Term Summary'!J$5) | K8: =SUM($E8:$J8) | L8: =+$K8-$J8 | N8: =IFERROR(SUM($G8:$I8)/$L8,"N/A") | O8: =IFERROR(SUM($H8:$I8)/$L8,"N/A") | P8: =IFERROR($I8/$L8,"N/A") | Q8: =IFERROR($J8/$K8,"N/A")
B9: 2018-1 | C9: =COUNTIFS('Term Loan'!$K:$K,'Term Summary'!$B$7,'Term Loan'!$L:$L,'Term Summary'!$B9) | D9: =COUNTIFS('Term Asset'!$E:$E,'Term Summary'!$B$7,'Term Asset'!$F:$F,'Term Summary'!$B9) | E9: =SUMIFS('Term Loan'!$P:$P,'Term Loan'!$K:$K,'Term Summary'!$B$7,'Term Loan'!$L:$L,'Term Summary'!$B9,'Term Loan'!$V:$V,'Term Summary'!E$5) | F9: =SUMIFS('Term Loan'!$P:$P,'Term Loan'!$K:$K,'Term Summary'!$B$7,'Term Loan'!$L:$L,'Term Summary'!$B9,'Term Loan'!$V:$V,'Term Summary'!F$5) | G9: =SUMIFS('Term Loan'!$P:$P,'Term Loan'!$K:$K,'Term Summary'!$B$7,'Term Loan'!$L:$L,'Term Summary'!$B9,'Term Loan'!$V:$V,'Term Summary'!G$5) | H9: =SUMIFS('Term Loan'!$P:$P,'Term Loan'!$K:$K,'Term Summary'!$B$7,'Term Loan'!$L:$L,'Term Summary'!$B9,'Term Loan'!$V:$V,'Term Summary'!H$5) | I9: =SUMIFS('Term Loan'!$P:$P,'Term Loan'!$K:$K,'Term Summary'!$B$7,'Term Loan'!$L:$L,'Term Summary'!$B9,'Term Loan'!$V:$V,'Term Summary'!I$5) | J9: =SUMIFS('Term Loan'!$P:$P,'Term Loan'!$K:$K,'Term Summary'!$B$7,'Term Loan'!$L:$L,'Term Summary'!$B9,'Term Loan'!$V:$V,'Term Summary'!J$5) | K9: =SUM($E9:$J9) | L9: =+$K9-$J9 | N9: =IFERROR(SUM($G9:$I9)/$L9,"N/A") | O9: =IFERROR(SUM($H9:$I9)/$L9,"N/A") | P9: =IFERROR($I9/$L9,"N/A") | Q9: =IFERROR($J9/$K9,"N/A")
B10: 2018-2 | C10: =COUNTIFS('Term Loan'!$K:$K,'Term Summary'!$B$7,'Term Loan'!$L:$L,'Term Summary'!$B10) | D10: =COUNTIFS('Term Asset'!$E:$E,'Term Summary'!$B$7,'Term Asset'!$F:$F,'Term Summary'!$B10) | E10: =SUMIFS('Term Loan'!$P:$P,'Term Loan'!$K:$K,'Term Summary'!$B$7,'Term Loan'!$L:$L,'Term Summary'!$B10,'Term Loan'!$V:$V,'Term Summary'!E$5) | F10: =SUMIFS('Term Loan'!$P:$P,'Term Loan'!$K:$K,'Term Summary'!$B$7,'Term Loan'!$L:$L,'Term Summary'!$B10,'Term Loan'!$V:$V,'Term Summary'!F$5) | G10: =SUMIFS('Term Loan'!$P:$P,'Term Loan'!$K:$K,'Term Summary'!$B$7,'Term Loan'!$L:$L,'Term Summary'!$B10,'Term Loan'!$V:$V,'Term Summary'!G$5) | H10: =SUMIFS('Term Loan'!$P:$P,'Term Loan'!$K:$K,'Term Summary'!$B$7,'Term Loan'!$L:$L,'Term Summary'!$B10,'Term Loan'!$V:$V,'Term Summary'!H$5) | I10: =SUMIFS('Term Loan'!$P:$P,'Term Loan'!$K:$K,'Term Summary'!$B$7,'Term Loan'!$L:$L,'Term Summary'!$B10,'Term Loan'!$V:$V,'Term Summary'!I$5) | J10: =SUMIFS('Term Loan'!$P:$P,'Term Loan'!$K:$K,'Term Summary'!$B$7,'Term Loan'!$L:$L,'Term Summary'!$B10,'Term Loan'!$V:$V,'Term Summary'!J$5) | K10: =SUM($E10:$J10) | L10: =+$K10-$J10 | N10: =IFERROR(SUM($G10:$I10)/$L10,"N/A") | O10: =IFERROR(SUM($H10:$I10)/$L10,"N/A") | P10: =IFERROR($I10/$L10,"N/A") | Q10: =IFERROR($J10/$K10,"N/A")
B11: 2019-1 | C11: =COUNTIFS('Term Loan'!$K:$K,'Term Summary'!$B$7,'Term Loan'!$L:$L,'Term Summary'!$B11) | D11: =COUNTIFS('Term Asset'!$E:$E,'Term Summary'!$B$7,'Term Asset'!$F:$F,'Term Summary'!$B11) | E11: =SUMIFS('Term Loan'!$P:$P,'Term Loan'!$K:$K,'Term Summary'!$B$7,'Term Loan'!$L:$L,'Term Summary'!$B11,'Term Loan'!$V:$V,'Term Summary'!E$5) | F11: =SUMIFS('Term Loan'!$P:$P,'Term Loan'!$K:$K,'Term Summary'!$B$7,'Term Loan'!$L:$L,'Term Summary'!$B11,'Term Loan'!$V:$V,'Term Summary'!F$5) | G11: =SUMIFS('Term Loan'!$P:$P,'Term Loan'!$K:$K,'Term Summary'!$B$7,'Term Loan'!$L:$L,'Term Summary'!$B11,'Term Loan'!$V:$V,'Term Summary'!G$5) | H11: =SUMIFS('Term Loan'!$P:$P,'Term Loan'!$K:$K,'Term Summary'!$B$7,'Term Loan'!$L:$L,'Term Summary'!$B11,'Term Loan'!$V:$V,'Term Summary'!H$5) | I11: =SUMIFS('Term Loan'!$P:$P,'Term Loan'!$K:$K,'Term Summary'!$B$7,'Term Loan'!$L:$L,'Term Summary'!$B11,'Term Loan'!$V:$V,'Term Summary'!I$5) | J11: =SUMIFS('Term Loan'!$P:$P,'Term Loan'!$K:$K,'Term Summary'!$B$7,'Term Loan'!$L:$L,'Term Summary'!$B11,'Term Loan'!$V:$V,'Term Summary'!J$5) | K11: =SUM($E11:$J11) | L11: =+$K11-$J11 | N11: =IFERROR(SUM($G11:$I11)/$L11,"N/A") | O11: =IFERROR(SUM($H11:$I11)/$L11,"N/A") | P11: =IFERROR($I11/$L11,"N/A") | Q11: =IFERROR($J11/$K11,"N/A")
B12: 2019-2 | C12: =COUNTIFS('Term Loan'!$K:$K,'Term Summary'!$B$7,'Term Loan'!$L:$L,'Term Summary'!$B12) | D12: =COUNTIFS('Term Asset'!$E:$E,'Term Summary'!$B$7,'Term Asset'!$F:$F,'Term Summary'!$B12) | E12: =SUMIFS('Term Loan'!$P:$P,'Term Loan'!$K:$K,'Term Summary'!$B$7,'Term Loan'!$L:$L,'Term Summary'!$B12,'Term Loan'!$V:$V,'Term Summary'!E$5) | F12: =SUMIFS('Term Loan'!$P:$P,'Term Loan'!$K:$K,'Term Summary'!$B$7,'Term Loan'!$L:$L,'Term Summary'!$B12,'Term Loan'!$V:$V,'Term Summary'!F$5) | G12: =SUMIFS('Term Loan'!$P:$P,'Term Loan'!$K:$K,'Term Summary'!$B$7,'Term Loan'!$L:$L,'Term Summary'!$B12,'Term Loan'!$V:$V,'Term Summary'!G$5) | H12: =SUMIFS('Term Loan'!$P:$P,'Term Loan'!$K:$K,'Term Summary'!$B$7,'Term Loan'!$L:$L,'Term Summary'!$B12,'Term Loan'!$V:$V,'Term Summary'!H$5) | I12: =SUMIFS('Term Loan'!$P:$P,'Term Loan'!$K:$K,'Term Summary'!$B$7,'Term Loan'!$L:$L,'Term Summary'!$B12,'Term Loan'!$V:$V,'Term Summary'!I$5) | J12: =SUMIFS('Term Loan'!$P:$P,'Term Loan'!$K:$K,'Term Summary'!$B$7,'Term Loan'!$L:$L,'Term Summary'!$B12,'Term Loan'!$V:$V,'Term Summary'!J$5) | K12: =SUM($E12:$J12) | L12: =+$K12-$J12 | N12: =IFERROR(SUM($G12:$I12)/$L12,"N/A") | O12: =IFERROR(SUM($H12:$I12)/$L12,"N/A") | P12: =IFERROR($I12/$L12,"N/A") | Q12: =IFERROR($J12/$K12,"N/A")
B13: 2019-3 | C13: =COUNTIFS('Term Loan'!$K:$K,'Term Summary'!$B$7,'Term Loan'!$L:$L,'Term Summary'!$B13) | D13: =COUNTIFS('Term Asset'!$E:$E,'Term Summary'!$B$7,'Term Asset'!$F:$F,'Term Summary'!$B13) | E13: =SUMIFS('Term Loan'!$P:$P,'Term Loan'!$K:$K,'Term Summary'!$B$7,'Term Loan'!$L:$L,'Term Summary'!$B13,'Term Loan'!$V:$V,'Term Summary'!E$5) | F13: =SUMIFS('Term Loan'!$P:$P,'Term Loan'!$K:$K,'Term Summary'!$B$7,'Term Loan'!$L:$L,'Term Summary'!$B13,'Term Loan'!$V:$V,'Term Summary'!F$5) | G13: =SUMIFS('Term Loan'!$P:$P,'Term Loan'!$K:$K,'Term Summary'!$B$7,'Term Loan'!$L:$L,'Term Summary'!$B13,'Term Loan'!$V:$V,'Term Summary'!G$5) | H13: =SUMIFS('Term Loan'!$P:$P,'Term Loan'!$K:$K,'Term Summary'!$B$7,'Term Loan'!$L:$L,'Term Summary'!$B13,'Term Loan'!$V:$V,'Term Summary'!H$5) | I13: =SUMIFS('Term Loan'!$P:$P,'Term Loan'!$K:$K,'Term Summary'!$B$7,'Term Loan'!$L:$L,'Term Summary'!$B13,'Term Loan'!$V:$V,'Term Summary'!I$5) | J13: =SUMIFS('Term Loan'!$P:$P,'Term Loan'!$K:$K,'Term Summary'!$B$7,'Term Loan'!$L:$L,'Term Summary'!$B13,'Term Loan'!$V:$V,'Term Summary'!J$5) | K13: =SUM($E13:$J13) | L13: =+$K13-$J13 | N13: =IFERROR(SUM($G13:$I13)/$L13,"N/A") | O13: =IFERROR(SUM($H13:$I13)/$L13,"N/A") | P13: =IFERROR($I13/$L13,"N/A") | Q13: =IFERROR($J13/$K13,"N/A")
B14: 2020-1 | C14: =COUNTIFS('Term Loan'!$K:$K,'Term Summary'!$B$7,'Term Loan'!$L:$L,'Term Summary'!$B14) | D14: =COUNTIFS('Term Asset'!$E:$E,'Term Summary'!$B$7,'Term Asset'!$F:$F,'Term Summary'!$B14) | E14: =SUMIFS('Term Loan'!$P:$P,'Term Loan'!$K:$K,'Term Summary'!$B$7,'Term Loan'!$L:$L,'Term Summary'!$B14,'Term Loan'!$V:$V,'Term Summary'!E$5) | F14: =SUMIFS('Term Loan'!$P:$P,'Term Loan'!$K:$K,'Term Summary'!$B$7,'Term Loan'!$L:$L,'Term Summary'!$B14,'Term Loan'!$V:$V,'Term Summary'!F$5) | G14: =SUMIFS('Term Loan'!$P:$P,'Term Loan'!$K:$K,'Term Summary'!$B$7,'Term Loan'!$L:$L,'Term Summary'!$B14,'Term Loan'!$V:$V,'Term Summary'!G$5) | H14: =SUMIFS('Term Loan'!$P:$P,'Term Loan'!$K:$K,'Term Summary'!$B$7,'Term Loan'!$L:$L,'Term Summary'!$B14,'Term Loan'!$V:$V,'Term Summary'!H$5) | I14: =SUMIFS('Term Loan'!$P:$P,'Term Loan'!$K:$K,'Term Summary'!$B$7,'Term Loan'!$L:$L,'Term Summary'!$B14,'Term Loan'!$V:$V,'Term Summary'!I$5) | J14: =SUMIFS('Term Loan'!$P:$P,'Term Loan'!$K:$K,'Term Summary'!$B$7,'Term Loan'!$L:$L,'Term Summary'!$B14,'Term Loan'!$V:$V,'Term Summary'!J$5) | K14: =SUM($E14:$J14) | L14: =+$K14-$J14 | N14: =IFERROR(SUM($G14:$I14)/$L14,"N/A") | O14: =IFERROR(SUM($H14:$I14)/$L14,"N/A") | P14: =IFERROR($I14/$L14,"N/A") | Q14: =IFERROR($J14/$K14,"N/A")
B15: 2020-2 | C15: =COUNTIFS('Term Loan'!$K:$K,'Term Summary'!$B$7,'Term Loan'!$L:$L,'Term Summary'!$B15) | D15: =COUNTIFS('Term Asset'!$E:$E,'Term Summary'!$B$7,'Term Asset'!$F:$F,'Term Summary'!$B15) | E15: =SUMIFS('Term Loan'!$P:$P,'Term Loan'!$K:$K,'Term Summary'!$B$7,'Term Loan'!$L:$L,'Term Summary'!$B15,'Term Loan'!$V:$V,'Term Summary'!E$5) | F15: =SUMIFS('Term Loan'!$P:$P,'Term Loan'!$K:$K,'Term Summary'!$B$7,'Term Loan'!$L:$L,'Term Summary'!$B15,'Term Loan'!$V:$V,'Term Summary'!F$5) | G15: =SUMIFS('Term Loan'!$P:$P,'Term Loan'!$K:$K,'Term Summary'!$B$7,'Term Loan'!$L:$L,'Term Summary'!$B15,'Term Loan'!$V:$V,'Term Summary'!G$5) | H15: =SUMIFS('Term Loan'!$P:$P,'Term Loan'!$K:$K,'Term Summary'!$B$7,'Term Loan'!$L:$L,'Term Summary'!$B15,'Term Loan'!$V:$V,'Term Summary'!H$5) | I15: =SUMIFS('Term Loan'!$P:$P,'Term Loan'!$K:$K,'Term Summary'!$B$7,'Term Loan'!$L:$L,'Term Summary'!$B15,'Term Loan'!$V:$V,'Term Summary'!I$5) | J15: =SUMIFS('Term Loan'!$P:$P,'Term Loan'!$K:$K,'Term Summary'!$B$7,'Term Loan'!$L:$L,'Term Summary'!$B15,'Term Loan'!$V:$V,'Term Summary'!J$5) | K15: =SUM($E15:$J15) | L15: =+$K15-$J15 | N15: =IFERROR(SUM($G15:$I15)/$L15,"N/A") | O15: =IFERROR(SUM($H15:$I15)/$L15,"N/A") | P15: =IFERROR($I15/$L15,"N/A") | Q15: =IFERROR($J15/$K15,"N/A")
B16: 2020-3 | C16: =COUNTIFS('Term Loan'!$K:$K,'Term Summary'!$B$7,'Term Loan'!$L:$L,'Term Summary'!$B16) | D16: =COUNTIFS('Term Asset'!$E:$E,'Term Summary'!$B$7,'Term Asset'!$F:$F,'Term Summary'!$B16) | E16: =SUMIFS('Term Loan'!$P:$P,'Term Loan'!$K:$K,'Term Summary'!$B$7,'Term Loan'!$L:$L,'Term Summary'!$B16,'Term Loan'!$V:$V,'Term Summary'!E$5) | F16: =SUMIFS('Term Loan'!$P:$P,'Term Loan'!$K:$K,'Term Summary'!$B$7,'Term Loan'!$L:$L,'Term Summary'!$B16,'Term Loan'!$V:$V,'Term Summary'!F$5) | G16: =SUMIFS('Term Loan'!$P:$P,'Term Loan'!$K:$K,'Term Summary'!$B$7,'Term Loan'!$L:$L,'Term Summary'!$B16,'Term Loan'!$V:$V,'Term Summary'!G$5) | H16: =SUMIFS('Term Loan'!$P:$P,'Term Loan'!$K:$K,'Term Summary'!$B$7,'Term Loan'!$L:$L,'Term Summary'!$B16,'Term Loan'!$V:$V,'Term Summary'!H$5) | I16: =SUMIFS('Term Loan'!$P:$P,'Term Loan'!$K:$K,'Term Summary'!$B$7,'Term Loan'!$L:$L,'Term Summary'!$B16,'Term Loan'!$V:$V,'Term Summary'!I$5) | J16: =SUMIFS('Term Loan'!$P:$P,'Term Loan'!$K:$K,'Term Summary'!$B$7,'Term Loan'!$L:$L,'Term Summary'!$B16,'Term Loan'!$V:$V,'Term Summary'!J$5) | K16: =SUM($E16:$J16) | L16: =+$K16-$J16 | N16: =IFERROR(SUM($G16:$I16)/$L16,"N/A") | O16: =IFERROR(SUM($H16:$I16)/$L16,"N/A") | P16: =IFERROR($I16/$L16,"N/A") | Q16: =IFERROR($J16/$K16,"N/A")
B17: 2020-4 | C17: =COUNTIFS('Term Loan'!$K:$K,'Term Summary'!$B$7,'Term Loan'!$L:$L,'Term Summary'!$B17) | D17: =COUNTIFS('Term Asset'!$E:$E,'Term Summary'!$B$7,'Term Asset'!$F:$F,'Term Summary'!$B17) | E17: =SUMIFS('Term Loan'!$P:$P,'Term Loan'!$K:$K,'Term Summary'!$B$7,'Term Loan'!$L:$L,'Term Summary'!$B17,'Term Loan'!$V:$V,'Term Summary'!E$5) | F17: =SUMIFS('Term Loan'!$P:$P,'Term Loan'!$K:$K,'Term Summary'!$B$7,'Term Loan'!$L:$L,'Term Summary'!$B17,'Term Loan'!$V:$V,'Term Summary'!F$5) | G17: =SUMIFS('Term Loan'!$P:$P,'Term Loan'!$K:$K,'Term Summary'!$B$7,'Term Loan'!$L:$L,'Term Summary'!$B17,'Term Loan'!$V:$V,'Term Summary'!G$5) | H17: =SUMIFS('Term Loan'!$P:$P,'Term Loan'!$K:$K,'Term Summary'!$B$7,'Term Loan'!$L:$L,'Term Summary'!$B17,'Term Loan'!$V:$V,'Term Summary'!H$5) | I17: =SUMIFS('Term Loan'!$P:$P,'Term Loan'!$K:$K,'Term Summary'!$B$7,'Term Loan'!$L:$L,'Term Summary'!$B17,'Term Loan'!$V:$V,'Term Summary'!I$5) | J17: =SUMIFS('Term Loan'!$P:$P,'Term Loan'!$K:$K,'Term Summary'!$B$7,'Term Loan'!$L:$L,'Term Summary'!$B17,'Term Loan'!$V:$V,'Term Summary'!J$5) | K17: =SUM($E17:$J17) | L17: =+$K17-$J17 | N17: =IFERROR(SUM($G17:$I17)/$L17,"N/A") | O17: =IFERROR(SUM($H17:$I17)/$L17,"N/A") | P17: =IFERROR($I17/$L17,"N/A") | Q17: =IFERROR($J17/$K17,"N/A")
B18: 2020-P1 | C18: =COUNTIFS('Term Loan'!$K:$K,'Term Summary'!$B$7,'Term Loan'!$L:$L,'Term Summary'!$B18) | D18: =COUNTIFS('Term Asset'!$E:$E,'Term Summary'!$B$7,'Term Asset'!$F:$F,'Term Summary'!$B18) | E18: =SUMIFS('Term Loan'!$P:$P,'Term Loan'!$K:$K,'Term Summary'!$B$7,'Term Loan'!$L:$L,'Term Summary'!$B18,'Term Loan'!$V:$V,'Term Summary'!E$5) | F18: =SUMIFS('Term Loan'!$P:$P,'Term Loan'!$K:$K,'Term Summary'!$B$7,'Term Loan'!$L:$L,'Term Summary'!$B18,'Term Loan'!$V:$V,'Term Summary'!F$5) | G18: =SUMIFS('Term Loan'!$P:$P,'Term Loan'!$K:$K,'Term Summary'!$B$7,'Term Loan'!$L:$L,'Term Summary'!$B18,'Term Loan'!$V:$V,'Term Summary'!G$5) | H18: =SUMIFS('Term Loan'!$P:$P,'Term Loan'!$K:$K,'Term Summary'!$B$7,'Term Loan'!$L:$L,'Term Summary'!$B18,'Term Loan'!$V:$V,'Term Summary'!H$5) | I18: =SUMIFS('Term Loan'!$P:$P,'Term Loan'!$K:$K,'Term Summary'!$B$7,'Term Loan'!$L:$L,'Term Summary'!$B18,'Term Loan'!$V:$V,'Term Summary'!I$5) | J18: =SUMIFS('Term Loan'!$P:$P,'Term Loan'!$K:$K,'Term Summary'!$B$7,'Term Loan'!$L:$L,'Term Summary'!$B18,'Term Loan'!$V:$V,'Term Summary'!J$5) | K18: =SUM($E18:$J18) | L18: =+$K18-$J18 | N18: =IFERROR(SUM($G18:$I18)/$L18,"N/A") | O18: =IFERROR(SUM($H18:$I18)/$L18,"N/A") | P18: =IFERROR($I18/$L18,"N/A") | Q18: =IFERROR($J18/$K18,"N/A")
B19: 2021-1 | C19: =COUNTIFS('Term Loan'!$K:$K,'Term Summary'!$B$7,'Term Loan'!$L:$L,'Term Summary'!$B19) | D19: =COUNTIFS('Term Asset'!$E:$E,'Term Summary'!$B$7,'Term Asset'!$F:$F,'Term Summary'!$B19) | E19: =SUMIFS('Term Loan'!$P:$P,'Term Loan'!$K:$K,'Term Summary'!$B$7,'Term Loan'!$L:$L,'Term Summary'!$B19,'Term Loan'!$V:$V,'Term Summary'!E$5) | F19: =SUMIFS('Term Loan'!$P:$P,'Term Loan'!$K:$K,'Term Summary'!$B$7,'Term Loan'!$L:$L,'Term Summary'!$B19,'Term Loan'!$V:$V,'Term Summary'!F$5) | G19: =SUMIFS('Term Loan'!$P:$P,'Term Loan'!$K:$K,'Term Summary'!$B$7,'Term Loan'!$L:$L,'Term Summary'!$B19,'Term Loan'!$V:$V,'Term Summary'!G$5) | H19: =SUMIFS('Term Loan'!$P:$P,'Term Loan'!$K:$K,'Term Summary'!$B$7,'Term Loan'!$L:$L,'Term Summary'!$B19,'Term Loan'!$V:$V,'Term Summary'!H$5) | I19: =SUMIFS('Term Loan'!$P:$P,'Term Loan'!$K:$K,'Term Summary'!$B$7,'Term Loan'!$L:$L,'Term Summary'!$B19,'Term Loan'!$V:$V,'Term Summary'!I$5) | J19: =SUMIFS('Term Loan'!$P:$P,'Term Loan'!$K:$K,'Term Summary'!$B$7,'Term Loan'!$L:$L,'Term Summary'!$B19,'Term Loan'!$V:$V,'Term Summary'!J$5) | K19: =SUM($E19:$J19) | L19: =+$K19-$J19 | N19: =IFERROR(SUM($G19:$I19)/$L19,"N/A") | O19: =IFERROR(SUM($H19:$I19)/$L19,"N/A") | P19: =IFERROR($I19/$L19,"N/A") | Q19: =IFERROR($J19/$K19,"N/A")
... B24: 2023-P1 | C24: =COUNTIFS('Term Loan'!$K:$K,'Term Summary'!$B$7,'Term Loan'!$L:$L,'Term Summary'!$B24) | D24: =COUNTIFS('Term Asset'!$E:$E,'Term Summary'!$B$7,'Term Asset'!$F:$F,'Term Summary'!$B24) | E24: =SUMIFS('Term Loan'!$P:$P,'Term Loan'!$K:$K,'Term Summary'!$B$7,'Term Loan'!$L:$L,'Term Summary'!$B24,'Term Loan'!$V:$V,'Term Summary'!E$5) | F24: =SUMIFS('Term Loan'!$P:$P,'Term Loan'!$K:$K,'Term Summary'!$B$7,'Term Loan'!$L:$L,'Term Summary'!$B24,'Term Loan'!$V:$V,'Term Summary'!F$5) | G24: =SUMIFS('Term Loan'!$P:$P,'Term Loan'!$K:$K,'Term Summary'!$B$7,'Term Loan'!$L:$L,'Term Summary'!$B24,'Term Loan'!$V:$V,'Term Summary'!G$5) | H24: =SUMIFS('Term Loan'!$P:$P,'Term Loan'!$K:$K,'Term Summary'!$B$7,'Term Loan'!$L:$L,'Term Summary'!$B24,'Term Loan'!$V:$V,'Term Summary'!H$5) | I24: =SUMIFS('Term Loan'!$P:$P,'Term Loan'!$K:$K,'Term Summary'!$B$7,'Term Loan'!$L:$L,'Term Summary'!$B24,'Term Loan'!$V:$V,'Term Summary'!I$5) | J24: =SUMIFS('Term Loan'!$P:$P,'Term Loan'!$K:$K,'Term Summary'!$B$7,'Term Loan'!$L:$L,'Term Summary'!$B24,'Term Loan'!$V:$V,'Term Summary'!J$5) | K24: =SUM($E24:$J24) | L24: =+$K24-$J24 | N24: =IFERROR(SUM($G24:$I24)/$L24,"N/A") | O24: =IFERROR(SUM($H24:$I24)/$L24,"N/A") | P24: =IFERROR($I24/$L24,"N/A") | Q24: =IFERROR($J24/$K24,"N/A")
B25: Mortgage Banking | C25: =COUNTIFS('Term Loan'!$K:$K,'Term Summary'!$B25) | D25: =COUNTIFS('Term Asset'!$E:$E,'Term Summary'!$B25) | E25: =SUMIFS('Term Loan'!$P:$P,'Term Loan'!$K:$K,'Term Summary'!$B25,'Term Loan'!$V:$V,'Term Summary'!E$5) | F25: =SUMIFS('Term Loan'!$P:$P,'Term Loan'!$K:$K,'Term Summary'!$B25,'Term Loan'!$V:$V,'Term Summary'!F$5) | G25: =SUMIFS('Term Loan'!$P:$P,'Term Loan'!$K:$K,'Term Summary'!$B25,'Term Loan'!$V:$V,'Term Summary'!G$5) | H25: =SUMIFS('Term Loan'!$P:$P,'Term Loan'!$K:$K,'Term Summary'!$B25,'Term Loan'!$V:$V,'Term Summary'!H$5) | I25: =SUMIFS('Term Loan'!$P:$P,'Term Loan'!$K:$K,'Term Summary'!$B25,'Term Loan'!$V:$V,'Term Summary'!I$5) | J25: =SUMIFS('Term Loan'!$P:$P,'Term Loan'!$K:$K,'Term Summary'!$B25,'Term Loan'!$V:$V,'Term Summary'!J$5) | K25: =SUM($E25:$J25) | L25: =+$K25-$J25 | N25: =IFERROR(SUM($G25:$I25)/$L25,"N/A") | O25: =IFERROR(SUM($H25:$I25)/$L25,"N/A") | P25: =IFERROR($I25/$L25,"N/A") | Q25: =IFERROR($J25/$K25,"N/A")
B26: DSCR | C26: =COUNTIFS('Term Loan'!$K:$K,'Term Summary'!$B26) | D26: =COUNTIFS('Term Asset'!$E:$E,'Term Summary'!$B26) | E26: =SUMIFS('Term Loan'!$P:$P,'Term Loan'!$K:$K,'Term Summary'!$B26,'Term Loan'!$V:$V,'Term Summary'!E$5) | F26: =SUMIFS('Term Loan'!$P:$P,'Term Loan'!$K:$K,'Term Summary'!$B26,'Term Loan'!$V:$V,'Term Summary'!F$5) | G26: =SUMIFS('Term Loan'!$P:$P,'Term Loan'!$K:$K,'Term Summary'!$B26,'Term Loan'!$V:$V,'Term Summary'!G$5) | H26: =SUMIFS('Term Loan'!$P:$P,'Term Loan'!$K:$K,'Term Summary'!$B26,'Term Loan'!$V:$V,'Term Summary'!H$5) | I26: =SUMIFS('Term Loan'!$P:$P,'Term Loan'!$K:$K,'Term Summary'!$B26,'Term Loan'!$V:$V,'Term Summary'!I$5) | J26: =SUMIFS('Term Loan'!$P:$P,'Term Loan'!$K:$K,'Term Summary'!$B26,'Term Loan'!$V:$V,'Term Summary'!J$5) | K26: =SUM($E26:$J26) | L26: =+$K26-$J26 | N26: =IFERROR(SUM($G26:$I26)/$L26,"N/A") | O26: =IFERROR(SUM($H26:$I26)/$L26,"N/A") | P26: =IFERROR($I26/$L26,"N/A") | Q26: =IFERROR($J26/$K26,"N/A")
B27: CPP JV | C27: =COUNTIFS('Term Loan'!$K:$K,'Term Summary'!$B27) | D27: =COUNTIFS('Term Asset'!$E:$E,'Term Summary'!$B27) | E27: =SUMIFS('Term Loan'!$P:$P,'Term Loan'!$K:$K,'Term Summary'!$B27,'Term Loan'!$V:$V,'Term Summary'!E$5) | F27: =SUMIFS('Term Loan'!$P:$P,'Term Loan'!$K:$K,'Term Summary'!$B27,'Term Loan'!$V:$V,'Term Summary'!F$5) | G27: =SUMIFS('Term Loan'!$P:$P,'Term Loan'!$K:$K,'Term Summary'!$B27,'Term Loan'!$V:$V,'Term Summary'!G$5) | H27: =SUMIFS('Term Loan'!$P:$P,'Term Loan'!$K:$K,'Term Summary'!$B27,'Term Loan'!$V:$V,'Term Summary'!H$5) | I27: =SUMIFS('Term Loan'!$P:$P,'Term Loan'!$K:$K,'Term Summary'!$B27,'Term Loan'!$V:$V,'Term Summary'!I$5) | J27: =SUMIFS('Term Loan'!$P:$P,'Term Loan'!$K:$K,'Term Summary'!$B27,'Term Loan'!$V:$V,'Term Summary'!J$5) | K27: =SUM($E27:$J27) | L27: =+$K27-$J27 | N27: =IFERROR(SUM($G27:$I27)/$L27,"N/A") | O27: =IFERROR(SUM($H27:$I27)/$L27,"N/A") | P27: =IFERROR($I27/$L27,"N/A") | Q27: =IFERROR($J27/$K27,"N/A")
B28: Apollo | C28: =COUNTIFS('Term Loan'!$K:$K,'Term Summary'!$B28) | D28: =COUNTIFS('Term Asset'!$E:$E,'Term Summary'!$B28) | E28: =SUMIFS('Term Loan'!$P:$P,'Term Loan'!$K:$K,'Term Summary'!$B28,'Term Loan'!$V:$V,'Term Summary'!E$5) | F28: =SUMIFS('Term Loan'!$P:$P,'Term Loan'!$K:$K,'Term Summary'!$B28,'Term Loan'!$V:$V,'Term Summary'!F$5) | G28: =SUMIFS('Term Loan'!$P:$P,'Term Loan'!$K:$K,'Term Summary'!$B28,'Term Loan'!$V:$V,'Term Summary'!G$5) | H28: =SUMIFS('Term Loan'!$P:$P,'Term Loan'!$K:$K,'Term Summary'!$B28,'Term Loan'!$V:$V,'Term Summary'!H$5) | I28: =SUMIFS('Term Loan'!$P:$P,'Term Loan'!$K:$K,'Term Summary'!$B28,'Term Loan'!$V:$V,'Term Summary'!I$5) | J28: =SUMIFS('Term Loan'!$P:$P,'Term Loan'!$K:$K,'Term Summary'!$B28,'Term Loan'!$V:$V,'Term Summary'!J$5) | K28: =SUM($E28:$J28) | L28: =+$K28-$J28 | N28: =IFERROR(SUM($G28:$I28)/$L28,"N/A") | O28: =IFERROR(SUM($H28:$I28)/$L28,"N/A") | P28: =IFERROR($I28/$L28,"N/A") | Q28: =IFERROR($J28/$K28,"N/A")
B29: Blackstone | C29: =COUNTIFS('Term Loan'!$K:$K,'Term Summary'!$B29) | D29: =COUNTIFS('Term Asset'!$E:$E,'Term Summary'!$B29) | E29: =SUMIFS('Term Loan'!$P:$P,'Term Loan'!$K:$K,'Term Summary'!$B29,'Term Loan'!$V:$V,'Term Summary'!E$5) | F29: =SUMIFS('Term Loan'!$P:$P,'Term Loan'!$K:$K,'Term Summary'!$B29,'Term Loan'!$V:$V,'Term Summary'!F$5) | G29: =SUMIFS('Term Loan'!$P:$P,'Term Loan'!$K:$K,'Term Summary'!$B29,'Term Loan'!$V:$V,'Term Summary'!G$5) | H29: =SUMIFS('Term Loan'!$P:$P,'Term Loan'!$K:$K,'Term Summary'!$B29,'Term Loan'!$V:$V,'Term Summary'!H$5) | I29: =SUMIFS('Term Loan'!$P:$P,'Term Loan'!$K:$K,'Term Summary'!$B29,'Term Loan'!$V:$V,'Term Summary'!I$5) | J29: =SUMIFS('Term Loan'!$P:$P,'Term Loan'!$K:$K,'Term Summary'!$B29,'Term Loan'!$V:$V,'Term Summary'!J$5) | K29: =SUM($E29:$J29) | L29: =+$K29-$J29 | N29: =IFERROR(SUM($G29:$I29)/$L29,"N/A") | O29: =IFERROR(SUM($H29:$I29)/$L29,"N/A") | P29: =IFERROR($I29/$L29,"N/A") | Q29: =IFERROR($J29/$K29,"N/A")
B30: Total Term | C30: =SUM(C$6:C$29)-SUM(C$8:C$24) | D30: =SUM(D$6:D$29)-SUM(D$8:D$24) | E30: =SUM(E$6:E$29)-SUM(E$8:E$24) | F30: =SUM(F$6:F$29)-SUM(F$8:F$24) | G30: =SUM(G$6:G$29)-SUM(G$8:G$24) | H30: =SUM(H$6:H$29)-SUM(H$8:H$24) | I30: =SUM(I$6:I$29)-SUM(I$8:I$24) | J30: =SUM(J$6:J$29)-SUM(J$8:J$24) | ... L30: =SUM(L$6:L$29)-SUM(L$8:L$24) | N30: =IFERROR(SUM($G30:$I30)/$L30,"N/A") | O30: =IFERROR(SUM($H30:$I30)/$L30,"N/A") | P30: =IFERROR($I30/$L30,"N/A") | Q30: =IFERROR($J30/$K30,"N/A")
B31: Total Term (Ex. Sold) | C31: =+C$30-SUM(C$28:C$29) | D31: =+D$30-SUM(D$28:D$29) | E31: =+E$30-SUM(E$28:E$29) | F31: =+F$30-SUM(F$28:F$29) | G31: =+G$30-SUM(G$28:G$29) | H31: =+H$30-SUM(H$28:H$29) | I31: =+I$30-SUM(I$28:I$29) | J31: =+J$30-SUM(J$28:J$29) | ... L31: =+L$30-SUM(L$28:L$29) | N31: =IFERROR(SUM($G31:$I31)/$L31,"N/A") | O31: =IFERROR(SUM($H31:$I31)/$L31,"N/A") | P31: =IFERROR($I31/$L31,"N/A") | Q31: =IFERROR($J31/$K31,"N/A")
B33: Legacy Term | C33: =+C$6 | D33: =+D$6 | E33: =+E$6 | F33: =+F$6 | G33: =+G$6 | H33: =+H$6 | I33: =+I$6 | J33: =+J$6 | ... L33: =+L$6 | N33: =IFERROR(SUM($G33:$I33)/$L33,"N/A") | O33: =IFERROR(SUM($H33:$I33)/$L33,"N/A") | P33: =IFERROR($I33/$L33,"N/A") | Q33: =IFERROR($J33/$K33,"N/A")
B34: Non-Legacy Term | C34: =+C$25+C$26 | D34: =+D$25+D$26 | E34: =+E$25+E$26 | F34: =+F$25+F$26 | G34: =+G$25+G$26 | H34: =+H$25+H$26 | I34: =+I$25+I$26 | J34: =+J$25+J$26 | ... L34: =+L$25+L$26 | N34: =IFERROR(SUM($G34:$I34)/$L34,"N/A") | O34: =IFERROR(SUM($H34:$I34)/$L34,"N/A") | P34: =IFERROR($I34/$L34,"N/A") | Q34: =IFERROR($J34/$K34,"N/A")
B35: Balance Sheet Term | C35: =SUM(C$33:C$34) | D35: =SUM(D$33:D$34) | E35: =SUM(E$33:E$34) | F35: =SUM(F$33:F$34) | G35: =SUM(G$33:G$34) | H35: =SUM(H$33:H$34) | I35: =SUM(I$33:I$34) | J35: =SUM(J$33:J$34) | ... L35: =SUM(L$33:L$34) | N35: =IFERROR(SUM($G35:$I35)/$L35,"N/A") | O35: =IFERROR(SUM($H35:$I35)/$L35,"N/A") | P35: =IFERROR($I35/$L35,"N/A") | Q35: =IFERROR($J35/$K35,"N/A")

Sheet Bridge Loan
V1: CALC
B2: Bridge Loan Level Data
V4: =+'Bridge Asset'!$CP$4 | Z4: =SUBTOTAL(9,Z6:Z1060)
B5: Portfolio | C5: Loan Buyer | D5: Financing | E5: Deal Number | F5: Servicer ID | G5: Servicer | H5: Deal Name | I5: Borrower Name | J5: Account | K5: Do Not Lend (Y/N) | L5: Primary Contact | M5: Number of Assets | N5: # of Units | O5: State(s) | P5: Origination Date | Q5: Last Funding Date | R5: Original Maturity Date | S5: Current Maturity Date | T5: Next Advance Maturity Date | U5: Next Payment Date | V5: Days Past Due | W5: Loan Level Delinquency | X5: Loan Commitment | Y5: Active Funded Amount | Z5: =+'Bridge Asset'!$AJ$5 | AA5: Suspense Balance | AB5: Remaining Commitment | AC5: Most Recent Valuation Date | AD5: Most Recent As-Is Value | AE5: Most Recent ARV | AF5: Initial Disbursement Funded | AG5: Renovation Holdback | AH5: Renovation HB Funded | AI5: Renovation HB Remaining | AJ5: Interest Allocation | AK5: Interest Allocation Funded | AL5: Loan Stage | AM5: Segment | AN5: Loan Type | AO5: Product Type | AP5: Product Sub Type | AQ5: Transaction Type | AR5: Project Strategy | AS5: Strategy Grouping | AT5: CV Originator | AU5: Active RM | AV5: Deal Intro Sub-Source | AW5: Referral Source Account | AX5: Referral Source Contact | AY5: 6/30 NPL | AZ5: Needs NPL Value | BA5: Special Focus (Y/N) | BB5: Asset Manager 1 | BC5: AM 1 Assigned Date | BD5: Asset Manager 2 | BE5: AM 2 Assigned Date | BF5: Construction Mgr. | BG5: CM Assigned Date | BH5: AM Commentary
V6: =+$V$4-$U6

Sheet Bridge Asset
AI1: CALC | CL1: CALC | CM1: CALC | CN1: CALC | CO1: CALC | CP1: CALC | CQ1: CALC | CR1: CALC | CS1: CALC | CT1: CALC | CU1: CALC | CV1: CALC | CW1: CALC | CX1: CALC | CY1: CALC | CZ1: CALC | DA1: CALC | DB1: CALC | DC1: CALC | DD1: CALC | DE1: CALC | DF1: CALC
B2: Bridge Asset Level Data
DE3: 46203
AJ4: =SUBTOTAL(9,AJ6:AJ4695) | CP4: 46178 | CQ4: =+$CP$4 | CV4: =EDATE(DE3,-6) | DE4: =+$DE$3-90
