Workbook

Sheet Summary
B2: Bridge DQ (2/28)
B3: * JV Loans Included at 100% UPB
C5: Current | D5: DQ 1-29 | E5: DQ 30-59 | F5: DQ 60-89 | G5: DQ 90+ | H5: REO | I5: Total | J5: Total Ex. REO | L5: DQ 30+ % | M5: DQ 60+ % | N5: DQ 90+ % | O5: REO %
B6: Renovate / Build to Rent | C6: =SUMIFS('Bridge Asset'!$AI:$AI,'Bridge Asset'!$BW:$BW,Summary!$B6,'Bridge Asset'!$CM:$CM,Summary!C$5) -> 0 | D6: =SUMIFS('Bridge Asset'!$AI:$AI,'Bridge Asset'!$BW:$BW,Summary!$B6,'Bridge Asset'!$CM:$CM,Summary!D$5) -> 0 | E6: =SUMIFS('Bridge Asset'!$AI:$AI,'Bridge Asset'!$BW:$BW,Summary!$B6,'Bridge Asset'!$CM:$CM,Summary!E$5) -> 0 | F6: =SUMIFS('Bridge Asset'!$AI:$AI,'Bridge Asset'!$BW:$BW,Summary!$B6,'Bridge Asset'!$CM:$CM,Summary!F$5) -> 0 | G6: =SUMIFS('Bridge Asset'!$AI:$AI,'Bridge Asset'!$BW:$BW,Summary!$B6,'Bridge Asset'!$CM:$CM,Summary!G$5) -> 0 | H6: =SUMIFS('Bridge Asset'!$AI:$AI,'Bridge Asset'!$BW:$BW,Summary!$B6,'Bridge Asset'!$CM:$CM,Summary!H$5) -> 0 | I6: =SUM($C6:$H6) -> 0 | J6: =+$I6-$H6 -> 0 | L6: =IFERROR(SUM($E6:$G6)/$J6,"N/A") -> N/A | M6: =IFERROR(SUM($F6:$G6)/$J6,"N/A") -> N/A | N6: =+$G6/$J6 -> #DIV/0! | O6: =+$H6/$J6 -> #DIV/0!
B7: Multifamily | C7: =SUMIFS('Bridge Asset'!$AI:$AI,'Bridge Asset'!$BW:$BW,Summary!$B7,'Bridge Asset'!$CM:$CM,Summary!C$5) -> 0 | D7: =SUMIFS('Bridge Asset'!$AI:$AI,'Bridge Asset'!$BW:$BW,Summary!$B7,'Bridge Asset'!$CM:$CM,Summary!D$5) -> 0 | E7: =SUMIFS('Bridge Asset'!$AI:$AI,'Bridge Asset'!$BW:$BW,Summary!$B7,'Bridge Asset'!$CM:$CM,Summary!E$5) -> 0 | F7: =SUMIFS('Bridge Asset'!$AI:$AI,'Bridge Asset'!$BW:$BW,Summary!$B7,'Bridge Asset'!$CM:$CM,Summary!F$5) -> 0 | G7: =SUMIFS('Bridge Asset'!$AI:$AI,'Bridge Asset'!$BW:$BW,Summary!$B7,'Bridge Asset'!$CM:$CM,Summary!G$5) -> 0 | H7: =SUMIFS('Bridge Asset'!$AI:$AI,'Bridge Asset'!$BW:$BW,Summary!$B7,'Bridge Asset'!$CM:$CM,Summary!H$5) -> 0 | I7: =SUM($C7:$H7) -> 0 | J7: =+$I7-$H7 -> 0 | L7: =IFERROR(SUM($E7:$G7)/$J7,"N/A") -> N/A | M7: =IFERROR(SUM($F7:$G7)/$J7,"N/A") -> N/A | N7: =+$G7/$J7 -> #DIV/0! | O7: =+$H7/$J7 -> #DIV/0!
B8: Single Asset Bridge | C8: =SUMIFS('Bridge Asset'!$AI:$AI,'Bridge Asset'!$BW:$BW,Summary!$B8,'Bridge Asset'!$CM:$CM,Summary!C$5) -> 0 | D8: =SUMIFS('Bridge Asset'!$AI:$AI,'Bridge Asset'!$BW:$BW,Summary!$B8,'Bridge Asset'!$CM:$CM,Summary!D$5) -> 0 | E8: =SUMIFS('Bridge Asset'!$AI:$AI,'Bridge Asset'!$BW:$BW,Summary!$B8,'Bridge Asset'!$CM:$CM,Summary!E$5) -> 0 | F8: =SUMIFS('Bridge Asset'!$AI:$AI,'Bridge Asset'!$BW:$BW,Summary!$B8,'Bridge Asset'!$CM:$CM,Summary!F$5) -> 0 | G8: =SUMIFS('Bridge Asset'!$AI:$AI,'Bridge Asset'!$BW:$BW,Summary!$B8,'Bridge Asset'!$CM:$CM,Summary!G$5) -> 0 | H8: =SUMIFS('Bridge Asset'!$AI:$AI,'Bridge Asset'!$BW:$BW,Summary!$B8,'Bridge Asset'!$CM:$CM,Summary!H$5) -> 0 | I8: =SUM($C8:$H8) -> 0 | J8: =+$I8-$H8 -> 0 | L8: =IFERROR(SUM($E8:$G8)/$J8,"N/A") -> N/A | M8: =IFERROR(SUM($F8:$G8)/$J8,"N/A") -> N/A | N8: =+$G8/$J8 -> #DIV/0! | O8: =+$H8/$J8 -> #DIV/0!
B9: Other | C9: =SUMIFS('Bridge Asset'!$AI:$AI,'Bridge Asset'!$BW:$BW,Summary!$B9,'Bridge Asset'!$CM:$CM,Summary!C$5) -> 0 | D9: =SUMIFS('Bridge Asset'!$AI:$AI,'Bridge Asset'!$BW:$BW,Summary!$B9,'Bridge Asset'!$CM:$CM,Summary!D$5) -> 0 | E9: =SUMIFS('Bridge Asset'!$AI:$AI,'Bridge Asset'!$BW:$BW,Summary!$B9,'Bridge Asset'!$CM:$CM,Summary!E$5) -> 0 | F9: =SUMIFS('Bridge Asset'!$AI:$AI,'Bridge Asset'!$BW:$BW,Summary!$B9,'Bridge Asset'!$CM:$CM,Summary!F$5) -> 0 | G9: =SUMIFS('Bridge Asset'!$AI:$AI,'Bridge Asset'!$BW:$BW,Summary!$B9,'Bridge Asset'!$CM:$CM,Summary!G$5) -> 0 | H9: =SUMIFS('Bridge Asset'!$AI:$AI,'Bridge Asset'!$BW:$BW,Summary!$B9,'Bridge Asset'!$CM:$CM,Summary!H$5) -> 0 | I9: =SUM($C9:$H9) -> 0 | J9: =+$I9-$H9 -> 0 | L9: =IFERROR(SUM($E9:$G9)/$J9,"N/A") -> N/A | M9: =IFERROR(SUM($F9:$G9)/$J9,"N/A") -> N/A | N9: =+$G9/$J9 -> #DIV/0! | O9: =+$H9/$J9 -> #DIV/0!
B10: Total Bridge | C10: =SUM(C$6:C$9) -> 0 | D10: =SUM(D$6:D$9) -> 0 | E10: =SUM(E$6:E$9) -> 0 | F10: =SUM(F$6:F$9) -> 0 | G10: =SUM(G$6:G$9) -> 0 | H10: =SUM(H$6:H$9) -> 0 | I10: =SUM(I$6:I$9) -> 0 | J10: =SUM(J$6:J$9) -> 0 | L10: =IFERROR(SUM($E10:$G10)/$J10,"N/A") -> N/A | M10: =IFERROR(SUM($F10:$G10)/$J10,"N/A") -> N/A | N10: =+$G10/$J10 -> #DIV/0! | O10: =+$H10/$J10 -> #DIV/0!
B12: Securitized Bridge | C12: =SUMIFS('Bridge Asset'!$AI:$AI,'Bridge Asset'!$BR:$BR,Summary!$B12,'Bridge Asset'!$CM:$CM,Summary!C$5) -> 0 | D12: =SUMIFS('Bridge Asset'!$AI:$AI,'Bridge Asset'!$BR:$BR,Summary!$B12,'Bridge Asset'!$CM:$CM,Summary!D$5) -> 0 | E12: =SUMIFS('Bridge Asset'!$AI:$AI,'Bridge Asset'!$BR:$BR,Summary!$B12,'Bridge Asset'!$CM:$CM,Summary!E$5) -> 0 | F12: =SUMIFS('Bridge Asset'!$AI:$AI,'Bridge Asset'!$BR:$BR,Summary!$B12,'Bridge Asset'!$CM:$CM,Summary!F$5) -> 0 | G12: =SUMIFS('Bridge Asset'!$AI:$AI,'Bridge Asset'!$BR:$BR,Summary!$B12,'Bridge Asset'!$CM:$CM,Summary!G$5) -> 0 | H12: =SUMIFS('Bridge Asset'!$AI:$AI,'Bridge Asset'!$BR:$BR,Summary!$B12,'Bridge Asset'!$CM:$CM,Summary!H$5) -> 0 | I12: =SUM($C12:$H12) -> 0 | J12: =+$I12-$H12 -> 0 | L12: =IFERROR(SUM($E12:$G12)/$J12,"N/A") -> N/A | M12: =IFERROR(SUM($F12:$G12)/$J12,"N/A") -> N/A | N12: =+$G12/$J12 -> #DIV/0! | O12: =+$H12/$J12 -> #DIV/0!
B13: Legacy | C13: =SUMIFS('Bridge Asset'!$AI:$AI,'Bridge Asset'!$BR:$BR,Summary!$B13,'Bridge Asset'!$CM:$CM,Summary!C$5) -> 0 | D13: =SUMIFS('Bridge Asset'!$AI:$AI,'Bridge Asset'!$BR:$BR,Summary!$B13,'Bridge Asset'!$CM:$CM,Summary!D$5) -> 0 | E13: =SUMIFS('Bridge Asset'!$AI:$AI,'Bridge Asset'!$BR:$BR,Summary!$B13,'Bridge Asset'!$CM:$CM,Summary!E$5) -> 0 | F13: =SUMIFS('Bridge Asset'!$AI:$AI,'Bridge Asset'!$BR:$BR,Summary!$B13,'Bridge Asset'!$CM:$CM,Summary!F$5) -> 0 | G13: =SUMIFS('Bridge Asset'!$AI:$AI,'Bridge Asset'!$BR:$BR,Summary!$B13,'Bridge Asset'!$CM:$CM,Summary!G$5) -> 0 | H13: =SUMIFS('Bridge Asset'!$AI:$AI,'Bridge Asset'!$BR:$BR,Summary!$B13,'Bridge Asset'!$CM:$CM,Summary!H$5) -> 0 | I13: =SUM($C13:$H13) -> 0 | J13: =+$I13-$H13 -> 0 | L13: =IFERROR(SUM($E13:$G13)/$J13,"N/A") -> N/A | M13: =IFERROR(SUM($F13:$G13)/$J13,"N/A") -> N/A | N13: =+$G13/$J13 -> #DIV/0! | O13: =+$H13/$J13 -> #DIV/0!
B14: SSP | C14: =SUMIFS('Bridge Asset'!$AI:$AI,'Bridge Asset'!$BR:$BR,Summary!$B14,'Bridge Asset'!$CM:$CM,Summary!C$5) -> 0 | D14: =SUMIFS('Bridge Asset'!$AI:$AI,'Bridge Asset'!$BR:$BR,Summary!$B14,'Bridge Asset'!$CM:$CM,Summary!D$5) -> 0 | E14: =SUMIFS('Bridge Asset'!$AI:$AI,'Bridge Asset'!$BR:$BR,Summary!$B14,'Bridge Asset'!$CM:$CM,Summary!E$5) -> 0 | F14: =SUMIFS('Bridge Asset'!$AI:$AI,'Bridge Asset'!$BR:$BR,Summary!$B14,'Bridge Asset'!$CM:$CM,Summary!F$5) -> 0 | G14: =SUMIFS('Bridge Asset'!$AI:$AI,'Bridge Asset'!$BR:$BR,Summary!$B14,'Bridge Asset'!$CM:$CM,Summary!G$5) -> 0 | H14: =SUMIFS('Bridge Asset'!$AI:$AI,'Bridge Asset'!$BR:$BR,Summary!$B14,'Bridge Asset'!$CM:$CM,Summary!H$5) -> 0 | I14: =SUM($C14:$H14) -> 0 | J14: =+$I14-$H14 -> 0 | L14: =IFERROR(SUM($E14:$G14)/$J14,"N/A") -> N/A | M14: =IFERROR(SUM($F14:$G14)/$J14,"N/A") -> N/A | N14: =+$G14/$J14 -> #DIV/0! | O14: =+$H14/$J14 -> #DIV/0!
B15: Mortgage Banking | C15: =SUMIFS('Bridge Asset'!$AI:$AI,'Bridge Asset'!$BR:$BR,Summary!$B15,'Bridge Asset'!$CM:$CM,Summary!C$5) -> 0 | D15: =SUMIFS('Bridge Asset'!$AI:$AI,'Bridge Asset'!$BR:$BR,Summary!$B15,'Bridge Asset'!$CM:$CM,Summary!D$5) -> 0 | E15: =SUMIFS('Bridge Asset'!$AI:$AI,'Bridge Asset'!$BR:$BR,Summary!$B15,'Bridge Asset'!$CM:$CM,Summary!E$5) -> 0 | F15: =SUMIFS('Bridge Asset'!$AI:$AI,'Bridge Asset'!$BR:$BR,Summary!$B15,'Bridge Asset'!$CM:$CM,Summary!F$5) -> 0 | G15: =SUMIFS('Bridge Asset'!$AI:$AI,'Bridge Asset'!$BR:$BR,Summary!$B15,'Bridge Asset'!$CM:$CM,Summary!G$5) -> 0 | H15: =SUMIFS('Bridge Asset'!$AI:$AI,'Bridge Asset'!$BR:$BR,Summary!$B15,'Bridge Asset'!$CM:$CM,Summary!H$5) -> 0 | I15: =SUM($C15:$H15) -> 0 | J15: =+$I15-$H15 -> 0 | L15: =IFERROR(SUM($E15:$G15)/$J15,"N/A") -> N/A | M15: =IFERROR(SUM($F15:$G15)/$J15,"N/A") -> N/A | N15: =+$G15/$J15 -> #DIV/0! | O15: =+$H15/$J15 -> #DIV/0!
B16: Oaktree JV | C16: =SUMIFS('Bridge Asset'!$AI:$AI,'Bridge Asset'!$BR:$BR,Summary!$B16,'Bridge Asset'!$CM:$CM,Summary!C$5) -> 0 | D16: =SUMIFS('Bridge Asset'!$AI:$AI,'Bridge Asset'!$BR:$BR,Summary!$B16,'Bridge Asset'!$CM:$CM,Summary!D$5) -> 0 | E16: =SUMIFS('Bridge Asset'!$AI:$AI,'Bridge Asset'!$BR:$BR,Summary!$B16,'Bridge Asset'!$CM:$CM,Summary!E$5) -> 0 | F16: =SUMIFS('Bridge Asset'!$AI:$AI,'Bridge Asset'!$BR:$BR,Summary!$B16,'Bridge Asset'!$CM:$CM,Summary!F$5) -> 0 | G16: =SUMIFS('Bridge Asset'!$AI:$AI,'Bridge Asset'!$BR:$BR,Summary!$B16,'Bridge Asset'!$CM:$CM,Summary!G$5) -> 0 | H16: =SUMIFS('Bridge Asset'!$AI:$AI,'Bridge Asset'!$BR:$BR,Summary!$B16,'Bridge Asset'!$CM:$CM,Summary!H$5) -> 0 | I16: =SUM($C16:$H16) -> 0 | J16: =+$I16-$H16 -> 0 | L16: =IFERROR(SUM($E16:$G16)/$J16,"N/A") -> N/A | M16: =IFERROR(SUM($F16:$G16)/$J16,"N/A") -> N/A | N16: =+$G16/$J16 -> #DIV/0! | O16: =+$H16/$J16 -> #DIV/0!
B17: CPP JV | C17: =SUMIFS('Bridge Asset'!$AI:$AI,'Bridge Asset'!$BR:$BR,Summary!$B17,'Bridge Asset'!$CM:$CM,Summary!C$5) -> 0 | D17: =SUMIFS('Bridge Asset'!$AI:$AI,'Bridge Asset'!$BR:$BR,Summary!$B17,'Bridge Asset'!$CM:$CM,Summary!D$5) -> 0 | E17: =SUMIFS('Bridge Asset'!$AI:$AI,'Bridge Asset'!$BR:$BR,Summary!$B17,'Bridge Asset'!$CM:$CM,Summary!E$5) -> 0 | F17: =SUMIFS('Bridge Asset'!$AI:$AI,'Bridge Asset'!$BR:$BR,Summary!$B17,'Bridge Asset'!$CM:$CM,Summary!F$5) -> 0 | G17: =SUMIFS('Bridge Asset'!$AI:$AI,'Bridge Asset'!$BR:$BR,Summary!$B17,'Bridge Asset'!$CM:$CM,Summary!G$5) -> 0 | H17: =SUMIFS('Bridge Asset'!$AI:$AI,'Bridge Asset'!$BR:$BR,Summary!$B17,'Bridge Asset'!$CM:$CM,Summary!H$5) -> 0 | I17: =SUM($C17:$H17) -> 0 | J17: =+$I17-$H17 -> 0 | L17: =IFERROR(SUM($E17:$G17)/$J17,"N/A") -> N/A | M17: =IFERROR(SUM($F17:$G17)/$J17,"N/A") -> N/A | N17: =+$G17/$J17 -> #DIV/0! | O17: =+$H17/$J17 -> #DIV/0!
B18: Sold Servicing Retained | C18: =SUMIFS('Bridge Asset'!$AI:$AI,'Bridge Asset'!$BR:$BR,Summary!$B18,'Bridge Asset'!$CM:$CM,Summary!C$5) -> 0 | D18: =SUMIFS('Bridge Asset'!$AI:$AI,'Bridge Asset'!$BR:$BR,Summary!$B18,'Bridge Asset'!$CM:$CM,Summary!D$5) -> 0 | E18: =SUMIFS('Bridge Asset'!$AI:$AI,'Bridge Asset'!$BR:$BR,Summary!$B18,'Bridge Asset'!$CM:$CM,Summary!E$5) -> 0 | F18: =SUMIFS('Bridge Asset'!$AI:$AI,'Bridge Asset'!$BR:$BR,Summary!$B18,'Bridge Asset'!$CM:$CM,Summary!F$5) -> 0 | G18: =SUMIFS('Bridge Asset'!$AI:$AI,'Bridge Asset'!$BR:$BR,Summary!$B18,'Bridge Asset'!$CM:$CM,Summary!G$5) -> 0 | H18: =SUMIFS('Bridge Asset'!$AI:$AI,'Bridge Asset'!$BR:$BR,Summary!$B18,'Bridge Asset'!$CM:$CM,Summary!H$5) -> 0 | I18: =SUM($C18:$H18) -> 0 | J18: =+$I18-$H18 -> 0 | L18: =IFERROR(SUM($E18:$G18)/$J18,"N/A") -> N/A | M18: =IFERROR(SUM($F18:$G18)/$J18,"N/A") -> N/A | N18: =+$G18/$J18 -> #DIV/0! | O18: =+$H18/$J18 -> #DIV/0!
B20: Legacy Bridge | C20: =+C$13 -> 0 | D20: =+D$13 -> 0 | E20: =+E$13 -> 0 | F20: =+F$13 -> 0 | G20: =+G$13 -> 0 | H20: =+H$13 -> 0 | I20: =+I$13 -> 0 | J20: =+J$13 -> 0 | L20: =IFERROR(SUM($E20:$G20)/$J20,"N/A") -> N/A | M20: =IFERROR(SUM($F20:$G20)/$J20,"N/A") -> N/A | N20: =+$G20/$J20 -> #DIV/0! | O20: =+$H20/$J20 -> #DIV/0!
B21: Non-Legacy Bridge | C21: =+C$12+C$15 -> 0 | D21: =+D$12+D$15 -> 0 | E21: =+E$12+E$15 -> 0 | F21: =+F$12+F$15 -> 0 | G21: =+G$12+G$15 -> 0 | H21: =+H$12+H$15 -> 0 | I21: =+I$12+I$15 -> 0 | J21: =+J$12+J$15 -> 0 | L21: =IFERROR(SUM($E21:$G21)/$J21,"N/A") -> N/A | M21: =IFERROR(SUM($F21:$G21)/$J21,"N/A") -> N/A | N21: =+$G21/$J21 -> #DIV/0! | O21: =+$H21/$J21 -> #DIV/0!
B22: Balance Sheet Bridge | C22: =SUM(C$20:C$21) -> 0 | D22: =SUM(D$20:D$21) -> 0 | E22: =SUM(E$20:E$21) -> 0 | F22: =SUM(F$20:F$21) -> 0 | G22: =SUM(G$20:G$21) -> 0 | H22: =SUM(H$20:H$21) -> 0 | I22: =SUM(I$20:I$21) -> 0 | J22: =SUM(J$20:J$21) -> 0 | L22: =IFERROR(SUM($E22:$G22)/$J22,"N/A") -> N/A | M22: =IFERROR(SUM($F22:$G22)/$J22,"N/A") -> N/A | N22: =+$G22/$J22 -> #DIV/0! | O22: =+$H22/$J22 -> #DIV/0!
B25: Term DQ (2/28)
B26: * JV Loans Included at 100% UPB
C28: =+C$5 -> Current | D28: =+D$5 -> DQ 1-29 | E28: =+E$5 -> DQ 30-59 | F28: =+F$5 -> DQ 60-89 | G28: =+G$5 -> DQ 90+ | H28: =+H$5 -> REO | I28: =+I$5 -> Total | J28: =+J$5 -> Total Ex. REO | L28: =+L$5 -> DQ 30+ % | M28: =+M$5 -> DQ 60+ % | N28: =+N$5 -> DQ 90+ % | O28: =+O$5 -> REO %
B29: Legacy | C29: =SUMIFS('Term Loan'!$P:$P,'Term Loan'!$K:$K,Summary!$B29,'Term Loan'!$V:$V,Summary!C$28) -> 0 | D29: =SUMIFS('Term Loan'!$P:$P,'Term Loan'!$K:$K,Summary!$B29,'Term Loan'!$V:$V,Summary!D$28) -> 0 | E29: =SUMIFS('Term Loan'!$P:$P,'Term Loan'!$K:$K,Summary!$B29,'Term Loan'!$V:$V,Summary!E$28) -> 0 | F29: =SUMIFS('Term Loan'!$P:$P,'Term Loan'!$K:$K,Summary!$B29,'Term Loan'!$V:$V,Summary!F$28) -> 0 | G29: =SUMIFS('Term Loan'!$P:$P,'Term Loan'!$K:$K,Summary!$B29,'Term Loan'!$V:$V,Summary!G$28) -> 0 | H29: =SUMIFS('Term Loan'!$P:$P,'Term Loan'!$K:$K,Summary!$B29,'Term Loan'!$V:$V,Summary!H$28) -> 0 | I29: =SUM($C29:$H29) -> 0 | J29: =+$I29-$H29 -> 0 | L29: =IFERROR(SUM($E29:$G29)/$J29,"N/A") -> N/A | M29: =IFERROR(SUM($F29:$G29)/$J29,"N/A") -> N/A | N29: =+$G29/$J29 -> #DIV/0! | O29: =+$H29/$J29 -> #DIV/0!
B30: Securitized Term | C30: =SUMIFS('Term Loan'!$P:$P,'Term Loan'!$K:$K,Summary!$B30,'Term Loan'!$V:$V,Summary!C$28) -> 0 | D30: =SUMIFS('Term Loan'!$P:$P,'Term Loan'!$K:$K,Summary!$B30,'Term Loan'!$V:$V,Summary!D$28) -> 0 | E30: =SUMIFS('Term Loan'!$P:$P,'Term Loan'!$K:$K,Summary!$B30,'Term Loan'!$V:$V,Summary!E$28) -> 0 | F30: =SUMIFS('Term Loan'!$P:$P,'Term Loan'!$K:$K,Summary!$B30,'Term Loan'!$V:$V,Summary!F$28) -> 0 | G30: =SUMIFS('Term Loan'!$P:$P,'Term Loan'!$K:$K,Summary!$B30,'Term Loan'!$V:$V,Summary!G$28) -> 0 | H30: =SUMIFS('Term Loan'!$P:$P,'Term Loan'!$K:$K,Summary!$B30,'Term Loan'!$V:$V,Summary!H$28) -> 0 | I30: =SUM($C30:$H30) -> 0 | J30: =+$I30-$H30 -> 0 | L30: =IFERROR(SUM($E30:$G30)/$J30,"N/A") -> N/A | M30: =IFERROR(SUM($F30:$G30)/$J30,"N/A") -> N/A | N30: =+$G30/$J30 -> #DIV/0! | O30: =+$H30/$J30 -> #DIV/0!
B31: Mortgage Banking | C31: =SUMIFS('Term Loan'!$P:$P,'Term Loan'!$K:$K,Summary!$B31,'Term Loan'!$V:$V,Summary!C$28) -> 0 | D31: =SUMIFS('Term Loan'!$P:$P,'Term Loan'!$K:$K,Summary!$B31,'Term Loan'!$V:$V,Summary!D$28) -> 0 | E31: =SUMIFS('Term Loan'!$P:$P,'Term Loan'!$K:$K,Summary!$B31,'Term Loan'!$V:$V,Summary!E$28) -> 0 | F31: =SUMIFS('Term Loan'!$P:$P,'Term Loan'!$K:$K,Summary!$B31,'Term Loan'!$V:$V,Summary!F$28) -> 0 | G31: =SUMIFS('Term Loan'!$P:$P,'Term Loan'!$K:$K,Summary!$B31,'Term Loan'!$V:$V,Summary!G$28) -> 0 | H31: =SUMIFS('Term Loan'!$P:$P,'Term Loan'!$K:$K,Summary!$B31,'Term Loan'!$V:$V,Summary!H$28) -> 0 | I31: =SUM($C31:$H31) -> 0 | J31: =+$I31-$H31 -> 0 | L31: =IFERROR(SUM($E31:$G31)/$J31,"N/A") -> N/A | M31: =IFERROR(SUM($F31:$G31)/$J31,"N/A") -> N/A | N31: =+$G31/$J31 -> #DIV/0! | O31: =+$H31/$J31 -> #DIV/0!
B32: CPP JV | C32: =SUMIFS('Term Loan'!$P:$P,'Term Loan'!$K:$K,Summary!$B32,'Term Loan'!$V:$V,Summary!C$28) -> 0 | D32: =SUMIFS('Term Loan'!$P:$P,'Term Loan'!$K:$K,Summary!$B32,'Term Loan'!$V:$V,Summary!D$28) -> 0 | E32: =SUMIFS('Term Loan'!$P:$P,'Term Loan'!$K:$K,Summary!$B32,'Term Loan'!$V:$V,Summary!E$28) -> 0 | F32: =SUMIFS('Term Loan'!$P:$P,'Term Loan'!$K:$K,Summary!$B32,'Term Loan'!$V:$V,Summary!F$28) -> 0 | G32: =SUMIFS('Term Loan'!$P:$P,'Term Loan'!$K:$K,Summary!$B32,'Term Loan'!$V:$V,Summary!G$28) -> 0 | H32: =SUMIFS('Term Loan'!$P:$P,'Term Loan'!$K:$K,Summary!$B32,'Term Loan'!$V:$V,Summary!H$28) -> 0 | I32: =SUM($C32:$H32) -> 0 | J32: =+$I32-$H32 -> 0 | L32: =IFERROR(SUM($E32:$G32)/$J32,"N/A") -> N/A | M32: =IFERROR(SUM($F32:$G32)/$J32,"N/A") -> N/A | N32: =+$G32/$J32 -> #DIV/0! | O32: =+$H32/$J32 -> #DIV/0!
B33: DSCR | C33: =SUMIFS('Term Loan'!$P:$P,'Term Loan'!$K:$K,Summary!$B33,'Term Loan'!$V:$V,Summary!C$28) -> 0 | D33: =SUMIFS('Term Loan'!$P:$P,'Term Loan'!$K:$K,Summary!$B33,'Term Loan'!$V:$V,Summary!D$28) -> 0 | E33: =SUMIFS('Term Loan'!$P:$P,'Term Loan'!$K:$K,Summary!$B33,'Term Loan'!$V:$V,Summary!E$28) -> 0 | F33: =SUMIFS('Term Loan'!$P:$P,'Term Loan'!$K:$K,Summary!$B33,'Term Loan'!$V:$V,Summary!F$28) -> 0 | G33: =SUMIFS('Term Loan'!$P:$P,'Term Loan'!$K:$K,Summary!$B33,'Term Loan'!$V:$V,Summary!G$28) -> 0 | H33: =SUMIFS('Term Loan'!$P:$P,'Term Loan'!$K:$K,Summary!$B33,'Term Loan'!$V:$V,Summary!H$28) -> 0 | I33: =SUM($C33:$H33) -> 0 | J33: =+$I33-$H33 -> 0 | L33: =IFERROR(SUM($E33:$G33)/$J33,"N/A") -> N/A | M33: =IFERROR(SUM($F33:$G33)/$J33,"N/A") -> N/A | N33: =+$G33/$J33 -> #DIV/0! | O33: =+$H33/$J33 -> #DIV/0!
B34: Total Term | C34: =SUM(C$29:C$33) -> 0 | D34: =SUM(D$29:D$33) -> 0 | E34: =SUM(E$29:E$33) -> 0 | F34: =SUM(F$29:F$33) -> 0 | G34: =SUM(G$29:G$33) -> 0 | H34: =SUM(H$29:H$33) -> 0 | I34: =SUM(I$29:I$33) -> 0 | J34: =SUM(J$29:J$33) -> 0 | L34: =IFERROR(SUM($E34:$G34)/$J34,"N/A") -> N/A | M34: =IFERROR(SUM($F34:$G34)/$J34,"N/A") -> N/A | N34: =+$G34/$J34 -> #DIV/0! | O34: =+$H34/$J34 -> #DIV/0!
B36: Legacy Term | C36: =+C$29 -> 0 | D36: =+D$29 -> 0 | E36: =+E$29 -> 0 | F36: =+F$29 -> 0 | G36: =+G$29 -> 0 | H36: =+H$29 -> 0 | I36: =+I$29 -> 0 | J36: =+J$29 -> 0 | L36: =IFERROR(SUM($E36:$G36)/$J36,"N/A") -> N/A | M36: =IFERROR(SUM($F36:$G36)/$J36,"N/A") -> N/A | N36: =+$G36/$J36 -> #DIV/0! | O36: =+$H36/$J36 -> #DIV/0!
B37: Non-Legacy Term | C37: =+C$31+C$33 -> 0 | D37: =+D$31+D$33 -> 0 | E37: =+E$31+E$33 -> 0 | F37: =+F$31+F$33 -> 0 | G37: =+G$31+G$33 -> 0 | H37: =+H$31+H$33 -> 0 | I37: =+I$31+I$33 -> 0 | J37: =+J$31+J$33 -> 0 | L37: =IFERROR(SUM($E37:$G37)/$J37,"N/A") -> N/A | M37: =IFERROR(SUM($F37:$G37)/$J37,"N/A") -> N/A | N37: =+$G37/$J37 -> #DIV/0! | O37: =+$H37/$J37 -> #DIV/0!
B38: Balance Sheet Term | C38: =SUM(C$36:C$37) -> 0 | D38: =SUM(D$36:D$37) -> 0 | E38: =SUM(E$36:E$37) -> 0 | F38: =SUM(F$36:F$37) -> 0 | G38: =SUM(G$36:G$37) -> 0 | H38: =SUM(H$36:H$37) -> 0 | I38: =SUM(I$36:I$37) -> 0 | J38: =SUM(J$36:J$37) -> 0 | L38: =IFERROR(SUM($E38:$G38)/$J38,"N/A") -> N/A | M38: =IFERROR(SUM($F38:$G38)/$J38,"N/A") -> N/A | N38: =+$G38/$J38 -> #DIV/0! | O38: =+$H38/$J38 -> #DIV/0!
B40: Apollo Global Management, Inc | C40: =SUMIFS('Term Loan'!$P:$P,'Term Loan'!$N:$N,Summary!$B40,'Term Loan'!$V:$V,Summary!C$28) -> 0 | D40: =SUMIFS('Term Loan'!$P:$P,'Term Loan'!$N:$N,Summary!$B40,'Term Loan'!$V:$V,Summary!D$28) -> 0 | E40: =SUMIFS('Term Loan'!$P:$P,'Term Loan'!$N:$N,Summary!$B40,'Term Loan'!$V:$V,Summary!E$28) -> 0 | F40: =SUMIFS('Term Loan'!$P:$P,'Term Loan'!$N:$N,Summary!$B40,'Term Loan'!$V:$V,Summary!F$28) -> 0 | G40: =SUMIFS('Term Loan'!$P:$P,'Term Loan'!$N:$N,Summary!$B40,'Term Loan'!$V:$V,Summary!G$28) -> 0 | H40: =SUMIFS('Term Loan'!$P:$P,'Term Loan'!$N:$N,Summary!$B40,'Term Loan'!$V:$V,Summary!H$28) -> 0 | I40: =SUM($C40:$H40) -> 0 | J40: =+$I40-$H40 -> 0 | L40: =IFERROR(SUM($E40:$G40)/$J40,"N/A") -> N/A | M40: =IFERROR(SUM($F40:$G40)/$J40,"N/A") -> N/A | N40: =+$G40/$J40 -> #DIV/0! | O40: =+$H40/$J40 -> #DIV/0!
B41: Blackstone Financial Services | C41: =SUMIFS('Term Loan'!$P:$P,'Term Loan'!$N:$N,Summary!$B41,'Term Loan'!$V:$V,Summary!C$28) -> 0 | D41: =SUMIFS('Term Loan'!$P:$P,'Term Loan'!$N:$N,Summary!$B41,'Term Loan'!$V:$V,Summary!D$28) -> 0 | E41: =SUMIFS('Term Loan'!$P:$P,'Term Loan'!$N:$N,Summary!$B41,'Term Loan'!$V:$V,Summary!E$28) -> 0 | F41: =SUMIFS('Term Loan'!$P:$P,'Term Loan'!$N:$N,Summary!$B41,'Term Loan'!$V:$V,Summary!F$28) -> 0 | G41: =SUMIFS('Term Loan'!$P:$P,'Term Loan'!$N:$N,Summary!$B41,'Term Loan'!$V:$V,Summary!G$28) -> 0 | H41: =SUMIFS('Term Loan'!$P:$P,'Term Loan'!$N:$N,Summary!$B41,'Term Loan'!$V:$V,Summary!H$28) -> 0 | I41: =SUM($C41:$H41) -> 0 | J41: =+$I41-$H41 -> 0 | L41: =IFERROR(SUM($E41:$G41)/$J41,"N/A") -> N/A | M41: =IFERROR(SUM($F41:$G41)/$J41,"N/A") -> N/A | N41: =+$G41/$J41 -> #DIV/0! | O41: =+$H41/$J41 -> #DIV/0!

Sheet Bridge Loan
V1: CALC
B2: Bridge Loan Data
V3: =+'Bridge Asset'!$CK$3 -> 46081 | Z3: =SUBTOTAL(9,#REF!) -> #REF!
B4: Portfolio | C4: Loan Buyer | D4: Financing | E4: Deal Number | F4: Servicer ID | G4: Servicer | H4: Deal Name | I4: Borrower Name | J4: Account | K4: Do Not Lend (Y/N) | L4: Primary Contact | M4: Number of Assets | N4: # of Units | O4: State(s) | P4: Origination Date | Q4: Last Funding Date | R4: Original Maturity Date | S4: Current Maturity Date | T4: Next Advance Maturity Date | U4: Next Payment Date | V4: Days Past Due | W4: Loan Level Delinquency | X4: Loan Commitment | Y4: Active Funded Amount | Z4: =+'Bridge Asset'!$AI$4 -> 2/28 UPB | AA4: Suspense Balance | AB4: Remaining Commitment | AC4: Most Recent Valuation Date | AD4: Most Recent As-Is Value | AE4: Most Recent ARV | AF4: Initial Disbursement Funded | AG4: Renovation Holdback | AH4: Renovation HB Funded | AI4: Renovation HB Remaining | AJ4: Interest Allocation | AK4: Interest Allocation Funded | AL4: Loan Stage | AM4: Segment | AN4: Product Type | AO4: Product Sub Type | AP4: Transaction Type | AQ4: Project Strategy | AR4: Strategy Grouping | AS4: CV Originator | AT4: Active RM | AU4: Deal Intro Sub-Source | AV4: Referral Source Account | AW4: Referral Source Contact | AX4: 3/31 NPL | AY4: Needs NPL Value | AZ4: Special Focus (Y/N) | BA4: Asset Manager 1 | BB4: AM 1 Assigned Date | BC4: Asset Manager 2 | BD4: AM 2 Assigned Date | BE4: Construction Mgr. | BF4: CM Assigned Date | BG4: AM Commentary

Sheet Bridge Asset
AH1: CALC | CH1: CALC | CI1: CALC | CJ1: CALC | CK1: CALC | CL1: CALC | CM1: CALC | CN1: CALC | CO1: CALC | CP1: CALC | CQ1: CALC | CR1: CALC | CS1: CALC | CT1: CALC | CU1: CALC | CW1: CALC | CX1: CALC | CY1: CALC | CZ1: CALC | DA1: CALC
B2: Bridge Asset Data | CZ2: 46112
AI3: =SUBTOTAL(9,#REF!) -> #REF! | CK3: 46081 | CL3: =+$CK$3 -> 46081 | CQ3: =EDATE(CZ2,-6) -> 45930 | CZ3: =+$CZ$2-90 -> 46022
B4: Portfolio | C4: Loan Buyer | D4: Financing | E4: Deal Number | F4: Servicer ID | G4: Servicer | H4: SF Yardi ID | I4: Asset ID | J4: Deal Name | K4: Borrower Entity | L4: Account Name | M4: Do Not Lend (Y/N) | N4: Primary Contact | O4: Address | P4: City | Q4: State | R4: Zip | S4: County | T4: CBSA | U4: APN | V4: Additional APNs | W4: # of Units | X4: Year Built | Y4: Square Feet | Z4: Origination Date | AA4: First Funding Date | AB4: Last Funding Date | AC4: Next Payment Date | AD4: Original Loan Maturity date | AE4: Current Loan Maturity date | AF4: Original Asset Maturity date | AG4: Current Asset Maturity Date | AH4: SF Funded Amount | AI4: 2/28 UPB | AJ4: Suspense Balance | AK4: Asset Manager 1 | AL4: AM 1 Assigned Date | AM4: Asset Manager 2 | AN4: AM 2 Assigned Date | AO4: Construction Mgr. | AP4: CM Assigned Date | AQ4: Remedy Plan | AR4: Delinquency Notes | AS4: Maturity Status | AT4: Is Special Asset (Y/N) | AU4: Special Asset Status | AV4: Special Asset Reason | AW4: Special Asset: Special Asset Status | AX4: Special Asset: Resolved Date | AY4: Forbearance Term Date | AZ4: REO Date | BA4: Origination Value Dt | BB4: Origination As-Is Value | BC4: Origination ARV | BD4: Most Recent Appraisal Order Date | BE4: Updated Valuation Date | BF4: Updated As-Is Value | BG4: Updated ARV | BH4: Initial Disbursement Funded | BI4: Renovation Holdback | BJ4: Renovation Holdback Funded | BK4: Renovation Holdback Remaining | BL4: Interest Allocation | BM4: Interest Allocation Funded | BN4: Title Company | BO4: Tax Due Date | BP4: Tax Frequency | BQ4: Tax Commentary | BR4: Segment | BS4: Product Type | BT4: Product Sub-Type | BU4: Transaction Type | BV4: Project Strategy | BW4: Strategy Grouping | BX4: Property Type | BY4: Originator | BZ4: Active RM | CA4: Deal Intro Sub-Source | CB4: Referral Source Account | CC4: Referral Source Contact | CD4: Loan Stage | CE4: Property Status | CF4: Servicer Status | CG4: Servicer Maturity Date | CH4: CV Maturity Date | CI4: Maturity Difference | CJ4: Maturity Date | CK4: Days to Maturity | CL4: Days Past Due | CM4: DQ Status | CN4: Most Recent Valuation Date | CO4: Most Recent As-Is Value | CP4: Most Recent ARV | CQ4: Needs NPL Value | CR4: Securitized (Y/N) | CS4: SSP JV (Y/N) | CT4: CPP JV (Y/N) | CU4: Oaktree JV (Y/N) | CV4: Legacy (Y/N) | CW4: Matured Loan (YN) | CX4: DQ 45+ Loan (Y/N) | CY4: SA Loan (Y/N) | CZ4: 3/31 NPL (Y/N) | DA4: Special Flag

Sheet Term Loan
AD1: 46112
B2: Term Loan Data
P3: =SUBTOTAL(9,#REF!) -> #REF! | U3: 46081 | AD3: =+$AD$1-90 -> 46022
B4: Deal Number | C4: Servicer ID | D4: Servicer | E4: SF Yardi ID | F4: Deal Name | G4: Borrower Entity | H4: Account Name | I4: Do Not Lend (Y/N) | J4: Portfolio | K4: Segment | L4: Financing | M4: CPP JV | N4: Loan Buyer | O4: Loan Amount | P4: 2/28 UPB | Q4: Origination Date | R4: Maturity Date | S4: Next Payment Date | T4: REO Date | U4: Days Past Due | V4: DQ Status | W4: Asset Manager | X4: Originator | Y4: Active RM | Z4: Deal Intro Sub-Source | AA4: Referral Source Account | AB4: Referral Source Contact | AC4: AM Commentary | AD4: Special Loans List (Y/N)
E5: x

Sheet Term Asset
B2: Term Asset Data
L3: =SUBTOTAL(9,#REF!) -> #REF!
B4: Deal Number | C4: Asset ID | D4: Address | E4: City | F4: State | G4: Zip | H4: CBSA | I4: # Units | J4: Property Type | K4: Property ALA | L4: =+'Term Loan'!$P$4 -> 2/28 UPB | M4: Special (Y/N) | N4: Value Date | O4: As-Is Value

Sheet Pacific Life
A1: Report Date | B1: =TODAY() -> 46091
A2: Account | B2: ID | C2: Previous Account | D2: Original Vendor | E2: Lender Account | F2: Lender Name | G2: Lender Ownership Pct | H2: Lender Funding Date | I2: Borrower Name | J2: Borrower Address | K2: Borrower City | L2: Borrower State | M2: Borrower Zip | N2: Home | O2: Work | P2: Mobile | Q2: Fax | R2: Original Balance | S2: Starting Balance | T2: Current Balance | U2: Note Rate | V2: Investor Rate | W2: Lien Position | X2: Escrow Payment | Y2: Suspense Pmt. | Z2: Loan Charges | AA2: Unpaid Late Charges | AB2: Unpaid Interest | AC2: Sr.Loan Amount | AD2: Unearned Disc. | AE2: Regular Payment | AF2: Status | AG2: Grace Days | AH2: Minimum Late Charge | AI2: Late Charge % | AJ2: Paid To Date | AK2: Boarding Date | AL2: Next Due Date | AM2: Maturity Date | AN2: Paid Off Date | AO2: Purchase Date | AP2: Origination Date | AQ2: Prop.Address | AR2: Prop.City | AS2: Prop.State | AT2: Prop.Zip | AU2: Appr.Value | AV2: Appr.Source | AW2: Appr.Date | AX2: LTV | AY2: Occupancy | AZ2: Prop.Type | BA2: ACH status | BB2: Rate Type | BC2: Deferred Principal Balance | BD2: Deferred Unpaid Interest | BE2: Deferred Unpaid Late Charges | BF2: Deferred Unpaid Loan Charges | BG2: Primary Purpose | BH2: Invest Asset Number | BI2: Days Late | BJ2: Loan Type | BK2: Draw Status | BL2: Draw Close Date | BM2: Maximum Draw | BN2: Funded Amount | BO2: Available Balance | BP2: Borrower Full Name | BQ2: CoBorrower | BR2: Restricted Balance | BS2: Default Interest Rate | BT2: Closed Date | BU2: Closed Reason | BV2: Default Interest Active Status | BW2: Escrow Balance | BX2: Reserve Balance | BY2: Borrower Email | BZ2: Sec Financing | CA2: Creation Date | CB2: Originator Loan Number | CC2: Borrower First Name | CD2: Borrower Middle Name | CE2: Borrower Last Name | CF2: Prepayment Expiration Date | CG2: Default Int Is Enabled | CH2: Other Payments
A3: 399147585 | B3: FCI | C3: 04461 | D3: 5ARCHASSET | E3: 14733 | F3: Pacific Life Insurance Company | G3: 100.000% | H3: 42887 | I3: R&M Commercial Real Estate, LLC Ron Jackson | J3: 335 Fields Drive | K3: Aberdeen | L3: NC | M3: 28315 | N3: (910)944-7453 | O3: (317)710-0126 | P3: (910)691-5907;(910)215-3841 | R3: 653300 | S3: 653300 | T3: 562247.7 | U3: 6.25000% | V3: 6.00000% | W3: 1st | X3: 0 | Y3: 0 | Z3: 25 | AA3: 402.25 | AB3: 0 | AD3: 0 | AE3: 4022.48 | AF3: Performing | AG3: 5 | AH3: 0 | AI3: 10.000% | AJ3: 46082 | AK3: 42831 | AL3: 46113 | AM3: 46478 | AP3: 42825 | AQ3: 5 Vail Place | AR3: Pinehurst | AS3: NC | AT3: 28374 | AU3: 0 | AX3: 28.550% | AY3: Vacant | AZ3: Residential Income 1-4 | BA3: Active | BB3: Fixed Rate | BC3: 0 | BD3: 0 | BE3: 0 | BF3: 0 | BG3: Business | BH3: 04461 | BI3: 0 | BJ3: Business Purpose Loan | BM3: 0 | BN3: 562247.7 | BO3: 0 | BP3: R&M Commercial Real Estate, LLCRon Jackson | BR3: 0 | BS3: 0 | BV3: FALSE | BW3: 0 | BX3: 0 | BY3: qualitybuilt1@hotmail.com | CA3: 42831.463 | CG3: FALSE | CH3: 0

Sheet SSP Loans
B2: SSP Pool
B4: Deal No. | C4: Deal Name
B5: 39268 | C5: The Conservancy BTR
B6: 40791 | C6: Moda Yorkville Townhomes
B7: 43229 | C7: JCF Huntsville 2 - 2022 Refinance
B8: 30518 | C8: JCF Lebanon, LLC
B9: 37572 | C9: Florio 3000 Ember MF
B10: 41482 | C10: The Wilcox
B11: 34430 | C11: Antioch (The Clublands)
B12: 41483 | C12: The Morgan
B13: 42814 | C13: Eagles Landing
B14: 38720 | C14: The View ABQ
B15: 38524 | C15: Cottages at Braselton - 2022
B16: 43438 | C16: Second City Rentals LOC 2
... B24: 39711 | C24: Florio 875 Conley MF

Sheet Legacy
B2: Legacy Bridge - 9/30 | G2: Legacy Term - 9/30
B3: 09302025 RWT Bridge Tape - 10.17.25 v1 | G3: =+B3 -> 09302025 RWT Bridge Tape - 10.17.25 v1
B5: Deal Number | C5: Deal Name | D5: Q3 Segment | G5: Deal Number | H5: Deal Name | I5: Q3 Segment
B6: 39499 | C6: AB Asset Management Louisiana CRE Portfolio | D6: Legacy | G6: 41494 | H6: Wieder BR 1 | I6: Legacy
B7: 39318 | C7: The Village at Kensington | D7: Legacy | G7: 48487 | H7: Bonner MA II | I7: Legacy
B8: 40113 | C8: Midwest Portfolio - OH | D8: Legacy | G8: 44177 | H8: Razjooyan DC 7 (2844 Langston Pl SE) | I8: Legacy
B9: 39584 | C9: The Jolie | D9: Legacy | G9: 20739 | H9: John Bailey WV | I9: Legacy
B10: 39894 | C10: 32 India St | D10: Legacy | G10: 20747 | H10: Equity Build 3 | I10: Legacy
B11: 47079 | C11: Bungalows on Village Way 2023 | D11: Legacy | G11: 54426 | H11: Bonham Capital | I11: Legacy
B12: 55629 | C12: Sutton Fields | D12: Legacy - Partial | G12: 50841 | H12: Cohen 1 | I12: Legacy
B13: 47464 | C13: Yorkminster 2023 | D13: Legacy | G13: 43422 | H13: Vision & Beyond 1 | I13: Legacy
B14: 41448 | C14: London Square & River Glen | D14: Legacy | G14: 43462 | H14: Vision & Beyond 2 | I14: Legacy
B15: 40945 | C15: Balfour Chamblee | D15: Paid Off
B16: 32506 | C16: Falcon Conley CV20 LLC (Florio Conley) | D16: Legacy
B17: 33732 | C17: JCF Panama Waterfront, LLC | D17: Legacy
B18: 49128 | C18: McKinley Homes | D18: Legacy
B19: 57543 | C19: Ark Homes for Rent (Settlers Preserve) LOC | D19: Legacy
B20: 40915 | C20: Mittelman Portfolio Baton Rouge | D20: REO
B21: 38947 | C21: TCY Capital Baton Rouge | D21: Legacy
B22: 41475 | C22: Polaris at East Point | D22: REO
B23: 33735 | C23: JCF Panama Clara, LLC | D23: Legacy
B24: 40923 | C24: Florio Mayson Turner MF | D24: REO
B25: 54718 | C25: Eden Hill Development Refi Renewal | D25: Legacy
B26: 56309 | C26: River View at Bexley | D26: Securitized Bridge
... B35: 40771 | C35: Midwest Portfolio - IN | D35: Legacy
B36: 5A-11833 | C36: CAPITAL HOMES INVESTMENTS LLC | D36: Legacy
B37: 41874 | C37: Stanley Wellington Bridge | D37: Paid Off
B38: 39386 | C38: Florio 8-10 Godwin MF | D38: Legacy
B39: 40426 | C39: Cornerstone Apartments Louisville | D39: Paid Off
B40: 2214-003504 | C40: 3651 Alta Mesa Drive | D40: Paid Off
B41: 41124 | C41: Florio 212-214 12th Ave MF | D41: Legacy
B42: 42295 | C42: 4646 Moncrief | D42: Paid Off
B43: 39392 | C43: Florio 21 Godwin MF | D43: Legacy
B44: 37683 | C44: ALJ Investmentss, Inc. | D44: Legacy
B45: 41118 | C45: Florio 41 Godwin MF | D45: Legacy
B46: 39795 | C46: Indigo 52, LLC | D46: Legacy
B47: 37185 | C47: SAP RE HOLDINGS LLC | D47: Legacy
B48: 57646 | C48: Tides Group I | D48: Securitized Bridge
B49: 37682 | C49: ALJ Portfolio II LLC | D49: Legacy
B50: 2340-003726 | C50: 2340-003726 - 27 Virginia Ave, 29 Virginia Ave & 31 Virginia Ave | D50: Legacy
...

Sheet Strategy Groupings
B2: Project Strategy Groupings | F2: Special Asset Officers
B4: Strategy | C4: Grouping | F4: Asset Manager 1 | G4: Y
B5: Renovate and Rent | C5: Renovate / Build to Rent | F5: Natasha Sango | G5: Y
B6: Build to Rent | C6: Renovate / Build to Rent | F6: Nerissa Pryba | G6: Y
B7: Portfolio Acquisition | C7: Renovate / Build to Rent | F7: John Sullivan | G7: Y
B8: Refinance (SFR / MFR) | C8: Renovate / Build to Rent | F8: Chris Sullivan | G8: Y
B9: Aggregation | C9: Renovate / Build to Rent | F9: Jim Casey | G9: Y
B10: Multifamily Light Lift | C10: Multifamily | F10: Jon Popovich | G10: Y
B11: Multifamily Light Lift/CLO | C11: Multifamily | F11: John Parsinen | G11: Y
B12: Multifamily Lease-Up/No Rehab | C12: Multifamily | F12: Matt Kim | G12: Y
B13: Multifamily Lease-Up/No Rehab/CLO | C13: Multifamily | F13: John Oakes | G13: Y
B14: Multifamily Heavy Lift | C14: Multifamily | F14: Cole Smith | G14: Y
B15: Multifamily Heavy Lift/CLO | C15: Multifamily
B16: Conversion to Multifamily | C16: Multifamily
B17: Multifamily GUC | C17: Multifamily
B18: Ground Up Construction | C18: Multifamily
B19: Townhome GUC | C19: Multifamily
B20: Fix and Flip | C20: Single Asset Bridge
